Workbook

Sheet Cover
A1: AMAVIO | Finanzmodell 36 Monate v1.8 FINAL
A2: Finale Baseline: dynamische Zahlungspläne, Plan-/Live-Liquidität, Steuerreserven, Szenarien und Modellchecks
B3: Kernfassung 1.8 · AMAVIO Living · Preis-, Cash- und Quellen-Synchronisierung · 30. Juli 2026
A4: Status | B4: =Checks!E18 -> CONDITIONAL
A5: Model purpose | B5: 36-Monats-Planung für ein kapitalarmes B2B-Projekt- und Servicemodell
A6: Capital convention | B6: 25.000 € geplante Startfinanzierung: 500 € Stammkapital + 24.500 € gesondert dokumentierte Zuführung/Darlehen
A7: Cash convention | B7: Plan- und Live-Sicht getrennt; verfügbare Liquidität nach Umsatzsteuer- und Ertragsteuerreserve
A8: Limit | B8: No object operation, tenant deposits, customer funds, receivables financing or input-VAT recovery modelled.
A9: Gate | B9: Live-Freigabe erst nach Eintrag des dokumentiert eingegangenen Finanzierungsbetrags
A10: Source | B10: Zahlungsprofile: Blueprint 40/40/20; Launch 30/30/30/10; Office Setup 50/30/20; laufende Leistungen im Voraus
A11: Owner | B11: Zaki Amawi / finance review required before use for commitments
A12: Version date | B12: 28. Juli 2026

Sheet Source_of_Truth
A1: AMAVIO Source of Truth v2.2
A2: Item | B2: Value | C2: Use
A3: Startfinanzierung | B3: 25000 | C3: Startkapitalbedarf; nicht Produktpreis
A4: Stammkapital | B4: 500 | C4: Teil der Startfinanzierung
A5: Zuführung / Darlehen | B5: 24500 | C5: Vor Live-Freigabe dokumentieren
A6: Launch-Preis netto | B6: 29500 | C6: Produktpreis zzgl. Fremdkosten
A7: Umsatz Jahr 1 | B7: 93500 | C7: Basiscase
A8: Umsatz Jahr 2 | B8: 269000 | C8: Basiscase
A9: Umsatz Jahr 3 | B9: 442000 | C9: Basiscase
A10: EBITDA Jahr 1 | B10: 34950 | C10: Recomputed audit
A11: EBITDA Jahr 2 | B11: 120320 | C11: Recomputed audit
A12: EBITDA Jahr 3 | B12: 169300 | C12: Recomputed audit

Sheet Funding_Scenarios
A1: AMAVIO Förder- und Finanzierungsbausteine v2.2
A2: Baustein | B2: Modellbehandlung | C2: Relevanz | D2: Voraussetzung | E2: Risiko/Limit | F2: Quelle
A3: KfW 266 Gewerbe zu Wohnen | B3: 0 EUR Basiscase; Zuschuss-Szenario | C3: Umnutzung Gewerbe zu Wohnen | D3: Antrag vor Beginn; Energieeffizienz-Experte; 10 Jahre Wohnnutzung | E3: De-minimis, nicht für Kaufpreis/Grundstück | F3: KfW 266
A4: KfW KFN 297/298 | B4: Fremdkapital-Szenario | C4: Klimafreundlicher Neubau | D4: KFN/QNG-Standards; Antrag vor Beginn | E4: Haushaltsmittel/technische Anforderungen | F4: KfW 297/298
A5: KfW KNN 296 | B5: Fremdkapital-Szenario | C5: Niedrigpreissegment | D5: Flächen-/Kosten-/Effizienzanforderungen | E5: Objektabhängig | F5: KfW 296
A6: BEG Sanierung/Einzelmaßnahmen | B6: CAPEX-/Tilgungs-Szenario | C6: Bestand/Sanierung/Heizung/Gebäudehülle | D6: Technische Mindestanforderungen | E6: Nicht pauschal planbar | F6: BMWE/KfW/BAFA
A7: Landeswohnraumförderung | B7: Objekt-Szenario | C7: Sozialer/gebundener Wohnraum | D7: Standort, Miet-/Belegungsbindung | E7: Kann Flexibilität Arbeitgeberwohnen begrenzen | F7: Landesförderbanken
A8: AfA / §7b EStG | B8: Investor-Cashflow-Hinweis | C8: Neubau/Mietwohnungsbau | D8: Steuerprüfung und Nutzungsart | E8: Temporäre Beherbergung kritisch | F8: EStG/BMF
A9: Arbeitgeberwohnung | B9: Kundenargument; kein UG-Zufluss | C9: Lohnsteuerlich strukturierbare Wohnlösung | D9: Payroll-/Steuerprüfung Arbeitgeber | E9: Sachbezug, ortsübliche Miete, SvEV | F9: BMF LStH/SvEV

Sheet Cash_Timing_Stress
A1: AMAVIO Cash Timing Stress v2.2
A2: Stress | B2: Annahme | C2: Wirkung | D2: Management-Reaktion | E2: Status
A3: Payment delay +60 days | B3: Gleicher Umsatz, aber Zahlung 60 Tage später | C3: Belastet freie Liquidität und USt-/Steuerreserve | D3: Forderungseinzug, Abschlagszahlung, GF-Bezug prüfen | E3: Zu modellieren in 13-Wochen-Forecast
A4: Payment delay +90 days | B4: Gleicher Umsatz, aber Zahlung 90 Tage später | C4: Live-Puffer kann trotz Jahresgewinn kritisch werden | D4: Keine neuen Fixkosten, Vorauszahlung verhandeln | E4: Zu modellieren in 13-Wochen-Forecast
A5: Launch shift +3 months | B5: Launch-Auftrag verschiebt sich um 3 Monate | C5: Umsatzpfad und Beleglogik verzögert | D5: Kostenstopp, Pipeline schärfen, Downside-Regel aktivieren | E5: P1 Gate
A6: Funding not documented | B6: 24.500 EUR nicht eingebracht | C6: Model release bleibt CONDITIONAL | D6: Keine Verpflichtungen vor Mittelzufluss | E6: Aktueller Live-Gate

Sheet P1_Gates
A1: AMAVIO P1 Gates vor externer Abgabe
A2: Gate | B2: Benötigter Nachweis | C2: Owner | D2: Status
A3: Startfinanzierung | B3: Geschäftskonto, Mittelzufluss, Darlehen/Zuführung, Beschluss | C3: Gründer / Steuerberatung | D3: Offen bis Nachweis
A4: Nachfragebeweis | B4: Pipeline, LOI, Angebot oder bezahltes Pilotmandat | C4: Gründer | D4: Offen
A5: §34c / Leistungsabgrenzung | B5: Kurzvermerk erlaubte/ausgeschlossene Tätigkeiten | C5: Rechtsprüfung | D5: Offen
A6: Unternehmensgegenstand | B6: Satzungsabgleich / Zieltext | C6: Rechts-/Notarprüfung | D6: Offen
A7: Cash Forecast | B7: 13-Wochen-Forecast mit Zahlungszielen und Steuerterminen | C7: Gründer / Buchhaltung | D7: Offen

Sheet Assumptions
A1: AMAVIO | Inputs – edit blue cells only
A3: Parameter | B3: Year 1 | C3: Year 2 | D3: Year 3 | E3: Unit | F3: Note
A4: Planned total start funding | B4: 25000 | C4: 0 | D4: 0 | E4: EUR | F4: €500 share capital + €24,500 documented contribution/loan; do not double count
A5: Documented received start funding | B5: 0 | C5: 0 | D5: 0 | E5: EUR | F5: Set to actual received amount before live use
A6: VAT rate | B6: 0.19 | C6: 0.19 | D6: 0.19 | E6: % | F6: VAT timing only; input VAT excluded
A7: Variable external cost rate | B7: 0.1 | C7: 0.12 | D7: 0.15 | E7: % revenue | F7: Non-recharged service external costs
A8: Monthly overhead | B8: 1600 | C8: 2200 | D8: 3200 | E8: EUR/month | F8: Software, insurance, marketing, advisers
A9: Founder gross compensation | B9: 2500 | C9: 3500 | D9: 5000 | E9: EUR/month | F9: Only after GF agreement + resolution + cash gate. HINWEIS: Gründungszuschuss BA prüfen (ggf. +€1.200-2.000/Monat persönlich für 6 Monate).
A10: Project coordination staff | B10: 0 | C10: 4000 | D10: 9000 | E10: EUR/month | F10: Only after personnel gate
A11: Depreciation | B11: 2000 | C11: 3000 | D11: 5000 | E11: EUR/year | F11: P&L only
A12: Capex | B12: 2000 | C12: 8000 | D12: 15000 | E12: EUR/year | F12: Cash use
A13: Minimum liquidity | B13: 10000 | C13: 15000 | D13: 25000 | E13: EUR | F13: Management threshold
A14: Downside revenue factor | B14: 0.45 | C14: 0.45 | D14: 0.45 | E14: % of Base | F14: Corrected to 45%
A15: Growth revenue factor | B15: 1.25 | C15: 1.25 | D15: 1.25 | E15: % of Base | F15: Planning sensitivity
... A17: Standard day rate | B17: 900 | C17: 900 | D17: 900 | E17: EUR/day | F17: Interne Kalibrierung gemäß Businessplan; client-facing Preise bleiben paketbasiert
A18: P0 finance status | B18: CONDITIONAL | C18: CONDITIONAL | D18: CONDITIONAL | E18: status | F18: Requires documented funding + legal/data/brand gates before commitments. Gate §34c GewO: Maklertätigkeit vor erstem Launch rechtlich klären.
A19: Tax reserve rate | B19: 0.3 | C19: 0.3 | D19: 0.3 | E19: % of positive EBT | F19: Vorsichtige Planreserve; keine Steuerberechnung
A20: Payment profile | F20: Editierbare Ratenprofile für Vertrags-Cashflow
A21: Blueprint instalments | B21: 0.4 | C21: 0.4 | D21: 0.2 | E21: % | F21: Auftrag / Optionsfreigabe / Übergabe
A22: Launch instalments | B22: 0.3 | C22: 0.3 | D22: 0.3 | E22: % | F22: Auftrag / Entscheidung / Bezugsfertigkeit
A23: Launch final instalment | B23: 0.1 | C23: 0 | D23: 0 | E23: % | F23: Stabilisierung
A24: Office Setup instalments | B24: 0.5 | C24: 0.3 | D24: 0.2 | E24: % | F24: Auftrag / Systemfreigabe / Go-live
A25: Model baseline | B25: 93,500 / 269,000 / 442,000 | E25: EUR | F25: Planumsatz Jahre 1–3

Sheet Contract_Cash
A1: AMAVIO | Contract value and planned cash collection schedule
A3: Contract / package | B3: Year | C3: Net contract value | D3: Payment logic | E3: M1 | F3: M2 | G3: M3 | H3: M4 | I3: M5 | J3: M6 | K3: M7 | L3: M8 | M3: M9 | N3: M10 | O3: M11 | P3: M12 | Q3: M13 | R3: M14 | S3: M15 | T3: M16 | U3: M17 | V3: M18 | W3: M19 | X3: M20 | Y3: M21 | Z3: M22 | AA3: M23 | AB3: M24 | AC3: M25 | AD3: M26 | AE3: M27 | AF3: M28 | AG3: M29 | AH3: M30 | AI3: M31 | AJ3: M32 | AK3: M33 | AL3: M34 | AM3: M35 | AN3: M36
A4: Blueprint 01 | B4: 1 | C4: 12500 | D4: 40 / 40 / 20 | E4: =IF(Schedule_Inputs!$C$4="Blueprint",$C4*IF(1-Schedule_Inputs!$B$4=0,Assumptions!$B$21,IF(1-Schedule_Inputs!$B$4=1,Assumptions!$C$21,IF(1-Schedule_Inputs!$B$4=2,Assumptions!$D$21,0))),IF(Schedule_Inputs!$C$4="Launch",$C4*IF(1-Schedule_Inputs!$B$4=0,Assumptions!$B$22,IF(1-Schedule_Inputs!$B$4=1,Assumptions!$C$22,IF(1-Schedule_Inputs!$B$4=2,Assumptions!$D$22,IF(1-Schedule_Inputs!$B$4=3,Assumptions!$B$23,0)))),IF(Schedule_Inputs!$C$4="Office Setup",$C4*IF(1-Schedule_Inputs!$B$4=0,Assumptions!$B$24,IF(1-Schedule_Inputs!$B$4=1,Assumptions!$C$24,IF(1-Schedule_Inputs!$B$4=2,Assumptions!$D$24,0))),IF(OR(Schedule_Inputs!$C$4="Monthly",Schedule_Inputs!$C$4="Periodic"),IF(AND(1>=Schedule_Inputs!$B$4,MOD(1-Schedule_Inputs!$B$4,Schedule_Inputs!$E$4)=0,(1-Schedule_Inputs!$B$4)/Schedule_Inputs!$E$4<Schedule_Inputs!$D$4),$C4/Schedule_Inputs!$D$4,0),0)))) -> 0 | F4: =IF(Schedule_Inputs!$C$4="Blueprint",$C4*IF(2-Schedule_Inputs!$B$4=0,Assumptions!$B$21,IF(2-Schedule_Inputs!$B$4=1,Assumptions!$C$21,IF(2-Schedule_Inputs!$B$4=2,Assumptions!$D$21,0))),IF(Schedule_Inputs!$C$4="Launch",$C4*IF(2-Schedule_Inputs!$B$4=0,Assumptions!$B$22,IF(2-Schedule_Inputs!$B$4=1,Assumptions!$C$22,IF(2-Schedule_Inputs!$B$4=2,Assumptions!$D$22,IF(2-Schedule_Inputs!$B$4=3,Assumptions!$B$23,0)))),IF(Schedule_Inputs!$C$4="Office Setup",$C4*IF(2-Schedule_Inputs!$B$4=0,Assumptions!$B$24,IF(2-Schedule_Inputs!$B$4=1,Assumptions!$C$24,IF(2-Schedule_Inputs!$B$4=2,Assumptions!$D$24,0))),IF(OR(Schedule_Inputs!$C$4="Monthly",Schedule_Inputs!$C$4="Periodic"),IF(AND(2>=Schedule_Inputs!$B$4,MOD(2-Schedule_Inputs!$B$4,Schedule_Inputs!$E$4)=0,(2-Schedule_Inputs!$B$4)/Schedule_Inputs!$E$4<Schedule_Inputs!$D$4),$C4/Schedule_Inputs!$D$4,0),0)))) -> 0 | G4: =IF(Schedule_Inputs!$C$4="Blueprint",$C4*IF(3-Schedule_Inputs!$B$4=0,Assumptions!$B$21,IF(3-Schedule_Inputs!$B$4=1,Assumptions!$C$21,IF(3-Schedule_Inputs!$B$4=2,Assumptions!$D$21,0))),IF(Schedule_Inputs!$C$4="Launch",$C4*IF(3-Schedule_Inputs!$B$4=0,Assumptions!$B$22,IF(3-Schedule_Inputs!$B$4=1,Assumptions!$C$22,IF(3-Schedule_Inputs!$B$4=2,Assumptions!$D$22,IF(3-Schedule_Inputs!$B$4=3,Assumptions!$B$23,0)))),IF(Schedule_Inputs!$C$4="Office Setup",$C4*IF(3-Schedule_Inputs!$B$4=0,Assumptions!$B$24,IF(3-Schedule_Inputs!$B$4=1,Assumptions!$C$24,IF(3-Schedule_Inputs!$B$4=2,Assumptions!$D$24,0))),IF(OR(Schedule_Inputs!$C$4="Monthly",Schedule_Inputs!$C$4="Periodic"),IF(AND(3>=Schedule_Inputs!$B$4,MOD(3-Schedule_Inputs!$B$4,Schedule_Inputs!$E$4)=0,(3-Schedule_Inputs!$B$4)/Schedule_Inputs!$E$4<Schedule_Inputs!$D$4),$C4/Schedule_Inputs!$D$4,0),0)))) -> 5000 | H4: =IF(Schedule_Inputs!$C$4="Blueprint",$C4*IF(4-Schedule_Inputs!$B$4=0,Assumptions!$B$21,IF(4-Schedule_Inputs!$B$4=1,Assumptions!$C$21,IF(4-Schedule_Inputs!$B$4=2,Assumptions!$D$21,0))),IF(Schedule_Inputs!$C$4="Launch",$C4*IF(4-Schedule_Inputs!$B$4=0,Assumptions!$B$22,IF(4-Schedule_Inputs!$B$4=1,Assumptions!$C$22,IF(4-Schedule_Inputs!$B$4=2,Assumptions!$D$22,IF(4-Schedule_Inputs!$B$4=3,Assumptions!$B$23,0)))),IF(Schedule_Inputs!$C$4="Office Setup",$C4*IF(4-Schedule_Inputs!$B$4=0,Assumptions!$B$24,IF(4-Schedule_Inputs!$B$4=1,Assumptions!$C$24,IF(4-Schedule_Inputs!$B$4=2,Assumptions!$D$24,0))),IF(OR(Schedule_Inputs!$C$4="Monthly",Schedule_Inputs!$C$4="Periodic"),IF(AND(4>=Schedule_Inputs!$B$4,MOD(4-Schedule_Inputs!$B$4,Schedule_Inputs!$E$4)=0,(4-Schedule_Inputs!$B$4)/Schedule_Inputs!$E$4<Schedule_Inputs!$D$4),$C4/Schedule_Inputs!$D$4,0),0)))) -> 5000 | I4: =IF(Schedule_Inputs!$C$4="Blueprint",$C4*IF(5-Schedule_Inputs!$B$4=0,Assumptions!$B$21,IF(5-Schedule_Inputs!$B$4=1,Assumptions!$C$21,IF(5-Schedule_Inputs!$B$4=2,Assumptions!$D$21,0))),IF(Schedule_Inputs!$C$4="Launch",$C4*IF(5-Schedule_Inputs!$B$4=0,Assumptions!$B$22,IF(5-Schedule_Inputs!$B$4=1,Assumptions!$C$22,IF(5-Schedule_Inputs!$B$4=2,Assumptions!$D$22,IF(5-Schedule_Inputs!$B$4=3,Assumptions!$B$23,0)))),IF(Schedule_Inputs!$C$4="Office Setup",$C4*IF(5-Schedule_Inputs!$B$4=0,Assumptions!$B$24,IF(5-Schedule_Inputs!$B$4=1,Assumptions!$C$24,IF(5-Schedule_Inputs!$B$4=2,Assumptions!$D$24,0))),IF(OR(Schedule_Inputs!$C$4="Monthly",Schedule_Inputs!$C$4="Periodic"),IF(AND(5>=Schedule_Inputs!$B$4,MOD(5-Schedule_Inputs!$B$4,Schedule_Inputs!$E$4)=0,(5-Schedule_Inputs!$B$4)/Schedule_Inputs!$E$4<Schedule_Inputs!$D$4),$C4/Schedule_Inputs!$D$4,0),0)))) -> 2500 | J4: =IF(Schedule_Inputs!$C$4="Blueprint",$C4*IF(6-Schedule_Inputs!$B$4=0,Assumptions!$B$21,IF(6-Schedule_Inputs!$B$4=1,Assumptions!$C$21,IF(6-Schedule_Inputs!$B$4=2,Assumptions!$D$21,0))),IF(Schedule_Inputs!$C$4="Launch",$C4*IF(6-Schedule_Inputs!$B$4=0,Assumptions!$B$22,IF(6-Schedule_Inputs!$B$4=1,Assumptions!$C$22,IF(6-Schedule_Inputs!$B$4=2,Assumptions!$D$22,IF(6-Schedule_Inputs!$B$4=3,Assumptions!$B$23,0)))),IF(Schedule_Inputs!$C$4="Office Setup",$C4*IF(6-Schedule_Inputs!$B$4=0,Assumptions!$B$24,IF(6-Schedule_Inputs!$B$4=1,Assumptions!$C$24,IF(6-Schedule_Inputs!$B$4=2,Assumptions!$D$24,0))),IF(OR(Schedule_Inputs!$C$4="Monthly",Schedule_Inputs!$C$4="Periodic"),IF(AND(6>=Schedule_Inputs!$B$4,MOD(6-Schedule_Inputs!$B$4,Schedule_Inputs!$E$4)=0,(6-Schedule_Inputs!$B$4)/Schedule_Inputs!$E$4<Schedule_Inputs!$D$4),$C4/Schedule_Inputs!$D$4,0),0)))) -> 0 | K4: =IF(Schedule_Inputs!$C$4="Blueprint",$C4*IF(7-Schedule_Inputs!$B$4=0,Assumptions!$B$21,IF(7-Schedule_Inputs!$B$4=1,Assumptions!$C$21,IF(7-Schedule_Inputs!$B$4=2,Assumptions!$D$21,0))),IF(Schedule_Inputs!$C$4="Launch",$C4*IF(7-Schedule_Inputs!$B$4=0,Assumptions!$B$22,IF(7-Schedule_Inputs!$B$4=1,Assumptions!$C$22,IF(7-Schedule_Inputs!$B$4=2,Assumptions!$D$22,IF(7-Schedule_Inputs!$B$4=3,Assumptions!$B$23,0)))),IF(Schedule_Inputs!$C$4="Office Setup",$C4*IF(7-Schedule_Inputs!$B$4=0,Assumptions!$B$24,IF(7-Schedule_Inputs!$B$4=1,Assumptions!$C$24,IF(7-Schedule_Inputs!$B$4=2,Assumptions!$D$24,0))),IF(OR(Schedule_Inputs!$C$4="Monthly",Schedule_Inputs!$C$4="Periodic"),IF(AND(7>=Schedule_Inputs!$B$4,MOD(7-Schedule_Inputs!$B$4,Schedule_Inputs!$E$4)=0,(7-Schedule_Inputs!$B$4)/Schedule_Inputs!$E$4<Schedule_Inputs!$D$4),$C4/Schedule_Inputs!$D$4,0),0)))) -> 0 | L4: =IF(Schedule_Inputs!$C$4="Blueprint",$C4*IF(8-Schedule_Inputs!$B$4=0,Assumptions!$B$21,IF(8-Schedule_Inputs!$B$4=1,Assumptions!$C$21,IF(8-Schedule_Inputs!$B$4=2,Assumptions!$D$21,0))),IF(Schedule_Inputs!$C$4="Launch",$C4*IF(8-Schedule_Inputs!$B$4=0,Assumptions!$B$22,IF(8-Schedule_Inputs!$B$4=1,Assumptions!$C$22,IF(8-Schedule_Inputs!$B$4=2,Assumptions!$D$22,IF(8-Schedule_Inputs!$B$4=3,Assumptions!$B$23,0)))),IF(Schedule_Inputs!$C$4="Office Setup",$C4*IF(8-Schedule_Inputs!$B$4=0,Assumptions!$B$24,IF(8-Schedule_Inputs!$B$4=1,Assumptions!$C$24,IF(8-Schedule_Inputs!$B$4=2,Assumptions!$D$24,0))),IF(OR(Schedule_Inputs!$C$4="Monthly",Schedule_Inputs!$C$4="Periodic"),IF(AND(8>=Schedule_Inputs!$B$4,MOD(8-Schedule_Inputs!$B$4,Schedule_Inputs!$E$4)=0,(8-Schedule_Inputs!$B$4)/Schedule_Inputs!$E$4<Schedule_Inputs!$D$4),$C4/Schedule_Inputs!$D$4,0),0)))) -> 0 | M4: =IF(Schedule_Inputs!$C$4="Blueprint",$C4*IF(9-Schedule_Inputs!$B$4=0,Assumptions!$B$21,IF(9-Schedule_Inputs!$B$4=1,Assumptions!$C$21,IF(9-Schedule_Inputs!$B$4=2,Assumptions!$D$21,0))),IF(Schedule_Inputs!$C$4="Launch",$C4*IF(9-Schedule_Inputs!$B$4=0,Assumptions!$B$22,IF(9-Schedule_Inputs!$B$4=1,Assumptions!$C$22,IF(9-Schedule_Inputs!$B$4=2,Assumptions!$D$22,IF(9-Schedule_Inputs!$B$4=3,Assumptions!$B$23,0)))),IF(Schedule_Inputs!$C$4="Office Setup",$C4*IF(9-Schedule_Inputs!$B$4=0,Assumptions!$B$24,IF(9-Schedule_Inputs!$B$4=1,Assumptions!$C$24,IF(9-Schedule_Inputs!$B$4=2,Assumptions!$D$24,0))),IF(OR(Schedule_Inputs!$C$4="Monthly",Schedule_Inputs!$C$4="Periodic"),IF(AND(9>=Schedule_Inputs!$B$4,MOD(9-Schedule_Inputs!$B$4,Schedule_Inputs!$E$4)=0,(9-Schedule_Inputs!$B$4)/Schedule_Inputs!$E$4<Schedule_Inputs!$D$4),$C4/Schedule_Inputs!$D$4,0),0)))) -> 0 | N4: =IF(Schedule_Inputs!$C$4="Blueprint",$C4*IF(10-Schedule_Inputs!$B$4=0,Assumptions!$B$21,IF(10-Schedule_Inputs!$B$4=1,Assumptions!$C$21,IF(10-Schedule_Inputs!$B$4=2,Assumptions!$D$21,0))),IF(Schedule_Inputs!$C$4="Launch",$C4*IF(10-Schedule_Inputs!$B$4=0,Assumptions!$B$22,IF(10-Schedule_Inputs!$B$4=1,Assumptions!$C$22,IF(10-Schedule_Inputs!$B$4=2,Assumptions!$D$22,IF(10-Schedule_Inputs!$B$4=3,Assumptions!$B$23,0)))),IF(Schedule_Inputs!$C$4="Office Setup",$C4*IF(10-Schedule_Inputs!$B$4=0,Assumptions!$B$24,IF(10-Schedule_Inputs!$B$4=1,Assumptions!$C$24,IF(10-Schedule_Inputs!$B$4=2,Assumptions!$D$24,0))),IF(OR(Schedule_Inputs!$C$4="Monthly",Schedule_Inputs!$C$4="Periodic"),IF(AND(10>=Schedule_Inputs!$B$4,MOD(10-Schedule_Inputs!$B$4,Schedule_Inputs!$E$4)=0,(10-Schedule_Inputs!$B$4)/Schedule_Inputs!$E$4<Schedule_Inputs!$D$4),$C4/Schedule_Inputs!$D$4,0),0)))) -> 0 | O4: =IF(Schedule_Inputs!$C$4="Blueprint",$C4*IF(11-Schedule_Inputs!$B$4=0,Assumptions!$B$21,IF(11-Schedule_Inputs!$B$4=1,Assumptions!$C$21,IF(11-Schedule_Inputs!$B$4=2,Assumptions!$D$21,0))),IF(Schedule_Inputs!$C$4="Launch",$C4*IF(11-Schedule_Inputs!$B$4=0,Assumptions!$B$22,IF(11-Schedule_Inputs!$B$4=1,Assumptions!$C$22,IF(11-Schedule_Inputs!$B$4=2,Assumptions!$D$22,IF(11-Schedule_Inputs!$B$4=3,Assumptions!$B$23,0)))),IF(Schedule_Inputs!$C$4="Office Setup",$C4*IF(11-Schedule_Inputs!$B$4=0,Assumptions!$B$24,IF(11-Schedule_Inputs!$B$4=1,Assumptions!$C$24,IF(11-Schedule_Inputs!$B$4=2,Assumptions!$D$24,0))),IF(OR(Schedule_Inputs!$C$4="Monthly",Schedule_Inputs!$C$4="Periodic"),IF(AND(11>=Schedule_Inputs!$B$4,MOD(11-Schedule_Inputs!$B$4,Schedule_Inputs!$E$4)=0,(11-Schedule_Inputs!$B$4)/Schedule_Inputs!$E$4<Schedule_Inputs!$D$4),$C4/Schedule_Inputs!$D$4,0),0)))) -> 0 | P4: =IF(Schedule_Inputs!$C$4="Blueprint",$C4*IF(12-Schedule_Inputs!$B$4=0,Assumptions!$B$21,IF(12-Schedule_Inputs!$B$4=1,Assumptions!$C$21,IF(12-Schedule_Inputs!$B$4=2,Assumptions!$D$21,0))),IF(Schedule_Inputs!$C$4="Launch",$C4*IF(12-Schedule_Inputs!$B$4=0,Assumptions!$B$22,IF(12-Schedule_Inputs!$B$4=1,Assumptions!$C$22,IF(12-Schedule_Inputs!$B$4=2,Assumptions!$D$22,IF(12-Schedule_Inputs!$B$4=3,Assumptions!$B$23,0)))),IF(Schedule_Inputs!$C$4="Office Setup",$C4*IF(12-Schedule_Inputs!$B$4=0,Assumptions!$B$24,IF(12-Schedule_Inputs!$B$4=1,Assumptions!$C$24,IF(12-Schedule_Inputs!$B$4=2,Assumptions!$D$24,0))),IF(OR(Schedule_Inputs!$C$4="Monthly",Schedule_Inputs!$C$4="Periodic"),IF(AND(12>=Schedule_Inputs!$B$4,MOD(12-Schedule_Inputs!$B$4,Schedule_Inputs!$E$4)=0,(12-Schedule_Inputs!$B$4)/Schedule_Inputs!$E$4<Schedule_Inputs!$D$4),$C4/Schedule_Inputs!$D$4,0),0)))) -> 0 | Q4: =IF(Schedule_Inputs!$C$4="Blueprint",$C4*IF(13-Schedule_Inputs!$B$4=0,Assumptions!$B$21,IF(13-Schedule_Inputs!$B$4=1,Assumptions!$C$21,IF(13-Schedule_Inputs!$B$4=2,Assumptions!$D$21,0))),IF(Schedule_Inputs!$C$4="Launch",$C4*IF(13-Schedule_Inputs!$B$4=0,Assumptions!$B$22,IF(13-Schedule_Inputs!$B$4=1,Assumptions!$C$22,IF(13-Schedule_Inputs!$B$4=2,Assumptions!$D$22,IF(13-Schedule_Inputs!$B$4=3,Assumptions!$B$23,0)))),IF(Schedule_Inputs!$C$4="Office Setup",$C4*IF(13-Schedule_Inputs!$B$4=0,Assumptions!$B$24,IF(13-Schedule_Inputs!$B$4=1,Assumptions!$C$24,IF(13-Schedule_Inputs!$B$4=2,Assumptions!$D$24,0))),IF(OR(Schedule_Inputs!$C$4="Monthly",Schedule_Inputs!$C$4="Periodic"),IF(AND(13>=Schedule_Inputs!$B$4,MOD(13-Schedule_Inputs!$B$4,Schedule_Inputs!$E$4)=0,(13-Schedule_Inputs!$B$4)/Schedule_Inputs!$E$4<Schedule_Inputs!$D$4),$C4/Schedule_Inputs!$D$4,0),0)))) -> 0 | R4: =IF(Schedule_Inputs!$C$4="Blueprint",$C4*IF(14-Schedule_Inputs!$B$4=0,Assumptions!$B$21,IF(14-Schedule_Inputs!$B$4=1,Assumptions!$C$21,IF(14-Schedule_Inputs!$B$4=2,Assumptions!$D$21,0))),IF(Schedule_Inputs!$C$4="Launch",$C4*IF(14-Schedule_Inputs!$B$4=0,Assumptions!$B$22,IF(14-Schedule_Inputs!$B$4=1,Assumptions!$C$22,IF(14-Schedule_Inputs!$B$4=2,Assumptions!$D$22,IF(14-Schedule_Inputs!$B$4=3,Assumptions!$B$23,0)))),IF(Schedule_Inputs!$C$4="Office Setup",$C4*IF(14-Schedule_Inputs!$B$4=0,Assumptions!$B$24,IF(14-Schedule_Inputs!$B$4=1,Assumptions!$C$24,IF(14-Schedule_Inputs!$B$4=2,Assumptions!$D$24,0))),IF(OR(Schedule_Inputs!$C$4="Monthly",Schedule_Inputs!$C$4="Periodic"),IF(AND(14>=Schedule_Inputs!$B$4,MOD(14-Schedule_Inputs!$B$4,Schedule_Inputs!$E$4)=0,(14-Schedule_Inputs!$B$4)/Schedule_Inputs!$E$4<Schedule_Inputs!$D$4),$C4/Schedule_Inputs!$D$4,0),0)))) -> 0 | S4: =IF(Schedule_Inputs!$C$4="Blueprint",$C4*IF(15-Schedule_Inputs!$B$4=0,Assumptions!$B$21,IF(15-Schedule_Inputs!$B$4=1,Assumptions!$C$21,IF(15-Schedule_Inputs!$B$4=2,Assumptions!$D$21,0))),IF(Schedule_Inputs!$C$4="Launch",$C4*IF(15-Schedule_Inputs!$B$4=0,Assumptions!$B$22,IF(15-Schedule_Inputs!$B$4=1,Assumptions!$C$22,IF(15-Schedule_Inputs!$B$4=2,Assumptions!$D$22,IF(15-Schedule_Inputs!$B$4=3,Assumptions!$B$23,0)))),IF(Schedule_Inputs!$C$4="Office Setup",$C4*IF(15-Schedule_Inputs!$B$4=0,Assumptions!$B$24,IF(15-Schedule_Inputs!$B$4=1,Assumptions!$C$24,IF(15-Schedule_Inputs!$B$4=2,Assumptions!$D$24,0))),IF(OR(Schedule_Inputs!$C$4="Monthly",Schedule_Inputs!$C$4="Periodic"),IF(AND(15>=Schedule_Inputs!$B$4,MOD(15-Schedule_Inputs!$B$4,Schedule_Inputs!$E$4)=0,(15-Schedule_Inputs!$B$4)/Schedule_Inputs!$E$4<Schedule_Inputs!$D$4),$C4/Schedule_Inputs!$D$4,0),0)))) -> 0 | T4: =IF(Schedule_Inputs!$C$4="Blueprint",$C4*IF(16-Schedule_Inputs!$B$4=0,Assumptions!$B$21,IF(16-Schedule_Inputs!$B$4=1,Assumptions!$C$21,IF(16-Schedule_Inputs!$B$4=2,Assumptions!$D$21,0))),IF(Schedule_Inputs!$C$4="Launch",$C4*IF(16-Schedule_Inputs!$B$4=0,Assumptions!$B$22,IF(16-Schedule_Inputs!$B$4=1,Assumptions!$C$22,IF(16-Schedule_Inputs!$B$4=2,Assumptions!$D$22,IF(16-Schedule_Inputs!$B$4=3,Assumptions!$B$23,0)))),IF(Schedule_Inputs!$C$4="Office Setup",$C4*IF(16-Schedule_Inputs!$B$4=0,Assumptions!$B$24,IF(16-Schedule_Inputs!$B$4=1,Assumptions!$C$24,IF(16-Schedule_Inputs!$B$4=2,Assumptions!$D$24,0))),IF(OR(Schedule_Inputs!$C$4="Monthly",Schedule_Inputs!$C$4="Periodic"),IF(AND(16>=Schedule_Inputs!$B$4,MOD(16-Schedule_Inputs!$B$4,Schedule_Inputs!$E$4)=0,(16-Schedule_Inputs!$B$4)/Schedule_Inputs!$E$4<Schedule_Inputs!$D$4),$C4/Schedule_Inputs!$D$4,0),0)))) -> 0 | U4: =IF(Schedule_Inputs!$C$4="Blueprint",$C4*IF(17-Schedule_Inputs!$B$4=0,Assumptions!$B$21,IF(17-Schedule_Inputs!$B$4=1,Assumptions!$C$21,IF(17-Schedule_Inputs!$B$4=2,Assumptions!$D$21,0))),IF(Schedule_Inputs!$C$4="Launch",$C4*IF(17-Schedule_Inputs!$B$4=0,Assumptions!$B$22,IF(17-Schedule_Inputs!$B$4=1,Assumptions!$C$22,IF(17-Schedule_Inputs!$B$4=2,Assumptions!$D$22,IF(17-Schedule_Inputs!$B$4=3,Assumptions!$B$23,0)))),IF(Schedule_Inputs!$C$4="Office Setup",$C4*IF(17-Schedule_Inputs!$B$4=0,Assumptions!$B$24,IF(17-Schedule_Inputs!$B$4=1,Assumptions!$C$24,IF(17-Schedule_Inputs!$B$4=2,Assumptions!$D$24,0))),IF(OR(Schedule_Inputs!$C$4="Monthly",Schedule_Inputs!$C$4="Periodic"),IF(AND(17>=Schedule_Inputs!$B$4,MOD(17-Schedule_Inputs!$B$4,Schedule_Inputs!$E$4)=0,(17-Schedule_Inputs!$B$4)/Schedule_Inputs!$E$4<Schedule_Inputs!$D$4),$C4/Schedule_Inputs!$D$4,0),0)))) -> 0 | V4: =IF(Schedule_Inputs!$C$4="Blueprint",$C4*IF(18-Schedule_Inputs!$B$4=0,Assumptions!$B$21,IF(18-Schedule_Inputs!$B$4=1,Assumptions!$C$21,IF(18-Schedule_Inputs!$B$4=2,Assumptions!$D$21,0))),IF(Schedule_Inputs!$C$4="Launch",$C4*IF(18-Schedule_Inputs!$B$4=0,Assumptions!$B$22,IF(18-Schedule_Inputs!$B$4=1,Assumptions!$C$22,IF(18-Schedule_Inputs!$B$4=2,Assumptions!$D$22,IF(18-Schedule_Inputs!$B$4=3,Assumptions!$B$23,0)))),IF(Schedule_Inputs!$C$4="Office Setup",$C4*IF(18-Schedule_Inputs!$B$4=0,Assumptions!$B$24,IF(18-Schedule_Inputs!$B$4=1,Assumptions!$C$24,IF(18-Schedule_Inputs!$B$4=2,Assumptions!$D$24,0))),IF(OR(Schedule_Inputs!$C$4="Monthly",Schedule_Inputs!$C$4="Periodic"),IF(AND(18>=Schedule_Inputs!$B$4,MOD(18-Schedule_Inputs!$B$4,Schedule_Inputs!$E$4)=0,(18-Schedule_Inputs!$B$4)/Schedule_Inputs!$E$4<Schedule_Inputs!$D$4),$C4/Schedule_Inputs!$D$4,0),0)))) -> 0 | W4: =IF(Schedule_Inputs!$C$4="Blueprint",$C4*IF(19-Schedule_Inputs!$B$4=0,Assumptions!$B$21,IF(19-Schedule_Inputs!$B$4=1,Assumptions!$C$21,IF(19-Schedule_Inputs!$B$4=2,Assumptions!$D$21,0))),IF(Schedule_Inputs!$C$4="Launch",$C4*IF(19-Schedule_Inputs!$B$4=0,Assumptions!$B$22,IF(19-Schedule_Inputs!$B$4=1,Assumptions!$C$22,IF(19-Schedule_Inputs!$B$4=2,Assumptions!$D$22,IF(19-Schedule_Inputs!$B$4=3,Assumptions!$B$23,0)))),IF(Schedule_Inputs!$C$4="Office Setup",$C4*IF(19-Schedule_Inputs!$B$4=0,Assumptions!$B$24,IF(19-Schedule_Inputs!$B$4=1,Assumptions!$C$24,IF(19-Schedule_Inputs!$B$4=2,Assumptions!$D$24,0))),IF(OR(Schedule_Inputs!$C$4="Monthly",Schedule_Inputs!$C$4="Periodic"),IF(AND(19>=Schedule_Inputs!$B$4,MOD(19-Schedule_Inputs!$B$4,Schedule_Inputs!$E$4)=0,(19-Schedule_Inputs!$B$4)/Schedule_Inputs!$E$4<Schedule_Inputs!$D$4),$C4/Schedule_Inputs!$D$4,0),0)))) -> 0 | X4: =IF(Schedule_Inputs!$C$4="Blueprint",$C4*IF(20-Schedule_Inputs!$B$4=0,Assumptions!$B$21,IF(20-Schedule_Inputs!$B$4=1,Assumptions!$C$21,IF(20-Schedule_Inputs!$B$4=2,Assumptions!$D$21,0))),IF(Schedule_Inputs!$C$4="Launch",$C4*IF(20-Schedule_Inputs!$B$4=0,Assumptions!$B$22,IF(20-Schedule_Inputs!$B$4=1,Assumptions!$C$22,IF(20-Schedule_Inputs!$B$4=2,Assumptions!$D$22,IF(20-Schedule_Inputs!$B$4=3,Assumptions!$B$23,0)))),IF(Schedule_Inputs!$C$4="Office Setup",$C4*IF(20-Schedule_Inputs!$B$4=0,Assumptions!$B$24,IF(20-Schedule_Inputs!$B$4=1,Assumptions!$C$24,IF(20-Schedule_Inputs!$B$4=2,Assumptions!$D$24,0))),IF(OR(Schedule_Inputs!$C$4="Monthly",Schedule_Inputs!$C$4="Periodic"),IF(AND(20>=Schedule_Inputs!$B$4,MOD(20-Schedule_Inputs!$B$4,Schedule_Inputs!$E$4)=0,(20-Schedule_Inputs!$B$4)/Schedule_Inputs!$E$4<Schedule_Inputs!$D$4),$C4/Schedule_Inputs!$D$4,0),0)))) -> 0 | Y4: =IF(Schedule_Inputs!$C$4="Blueprint",$C4*IF(21-Schedule_Inputs!$B$4=0,Assumptions!$B$21,IF(21-Schedule_Inputs!$B$4=1,Assumptions!$C$21,IF(21-Schedule_Inputs!$B$4=2,Assumptions!$D$21,0))),IF(Schedule_Inputs!$C$4="Launch",$C4*IF(21-Schedule_Inputs!$B$4=0,Assumptions!$B$22,IF(21-Schedule_Inputs!$B$4=1,Assumptions!$C$22,IF(21-Schedule_Inputs!$B$4=2,Assumptions!$D$22,IF(21-Schedule_Inputs!$B$4=3,Assumptions!$B$23,0)))),IF(Schedule_Inputs!$C$4="Office Setup",$C4*IF(21-Schedule_Inputs!$B$4=0,Assumptions!$B$24,IF(21-Schedule_Inputs!$B$4=1,Assumptions!$C$24,IF(21-Schedule_Inputs!$B$4=2,Assumptions!$D$24,0))),IF(OR(Schedule_Inputs!$C$4="Monthly",Schedule_Inputs!$C$4="Periodic"),IF(AND(21>=Schedule_Inputs!$B$4,MOD(21-Schedule_Inputs!$B$4,Schedule_Inputs!$E$4)=0,(21-Schedule_Inputs!$B$4)/Schedule_Inputs!$E$4<Schedule_Inputs!$D$4),$C4/Schedule_Inputs!$D$4,0),0)))) -> 0 | Z4: =IF(Schedule_Inputs!$C$4="Blueprint",$C4*IF(22-Schedule_Inputs!$B$4=0,Assumptions!$B$21,IF(22-Schedule_Inputs!$B$4=1,Assumptions!$C$21,IF(22-Schedule_Inputs!$B$4=2,Assumptions!$D$21,0))),IF(Schedule_Inputs!$C$4="Launch",$C4*IF(22-Schedule_Inputs!$B$4=0,Assumptions!$B$22,IF(22-Schedule_Inputs!$B$4=1,Assumptions!$C$22,IF(22-Schedule_Inputs!$B$4=2,Assumptions!$D$22,IF(22-Schedule_Inputs!$B$4=3,Assumptions!$B$23,0)))),IF(Schedule_Inputs!$C$4="Office Setup",$C4*IF(22-Schedule_Inputs!$B$4=0,Assumptions!$B$24,IF(22-Schedule_Inputs!$B$4=1,Assumptions!$C$24,IF(22-Schedule_Inputs!$B$4=2,Assumptions!$D$24,0))),IF(OR(Schedule_Inputs!$C$4="Monthly",Schedule_Inputs!$C$4="Periodic"),IF(AND(22>=Schedule_Inputs!$B$4,MOD(22-Schedule_Inputs!$B$4,Schedule_Inputs!$E$4)=0,(22-Schedule_Inputs!$B$4)/Schedule_Inputs!$E$4<Schedule_Inputs!$D$4),$C4/Schedule_Inputs!$D$4,0),0)))) -> 0 | AA4: =IF(Schedule_Inputs!$C$4="Blueprint",$C4*IF(23-Schedule_Inputs!$B$4=0,Assumptions!$B$21,IF(23-Schedule_Inputs!$B$4=1,Assumptions!$C$21,IF(23-Schedule_Inputs!$B$4=2,Assumptions!$D$21,0))),IF(Schedule_Inputs!$C$4="Launch",$C4*IF(23-Schedule_Inputs!$B$4=0,Assumptions!$B$22,IF(23-Schedule_Inputs!$B$4=1,Assumptions!$C$22,IF(23-Schedule_Inputs!$B$4=2,Assumptions!$D$22,IF(23-Schedule_Inputs!$B$4=3,Assumptions!$B$23,0)))),IF(Schedule_Inputs!$C$4="Office Setup",$C4*IF(23-Schedule_Inputs!$B$4=0,Assumptions!$B$24,IF(23-Schedule_Inputs!$B$4=1,Assumptions!$C$24,IF(23-Schedule_Inputs!$B$4=2,Assumptions!$D$24,0))),IF(OR(Schedule_Inputs!$C$4="Monthly",Schedule_Inputs!$C$4="Periodic"),IF(AND(23>=Schedule_Inputs!$B$4,MOD(23-Schedule_Inputs!$B$4,Schedule_Inputs!$E$4)=0,(23-Schedule_Inputs!$B$4)/Schedule_Inputs!$E$4<Schedule_Inputs!$D$4),$C4/Schedule_Inputs!$D$4,0),0)))) -> 0 | AB4: =IF(Schedule_Inputs!$C$4="Blueprint",$C4*IF(24-Schedule_Inputs!$B$4=0,Assumptions!$B$21,IF(24-Schedule_Inputs!$B$4=1,Assumptions!$C$21,IF(24-Schedule_Inputs!$B$4=2,Assumptions!$D$21,0))),IF(Schedule_Inputs!$C$4="Launch",$C4*IF(24-Schedule_Inputs!$B$4=0,Assumptions!$B$22,IF(24-Schedule_Inputs!$B$4=1,Assumptions!$C$22,IF(24-Schedule_Inputs!$B$4=2,Assumptions!$D$22,IF(24-Schedule_Inputs!$B$4=3,Assumptions!$B$23,0)))),IF(Schedule_Inputs!$C$4="Office Setup",$C4*IF(24-Schedule_Inputs!$B$4=0,Assumptions!$B$24,IF(24-Schedule_Inputs!$B$4=1,Assumptions!$C$24,IF(24-Schedule_Inputs!$B$4=2,Assumptions!$D$24,0))),IF(OR(Schedule_Inputs!$C$4="Monthly",Schedule_Inputs!$C$4="Periodic"),IF(AND(24>=Schedule_Inputs!$B$4,MOD(24-Schedule_Inputs!$B$4,Schedule_Inputs!$E$4)=0,(24-Schedule_Inputs!$B$4)/Schedule_Inputs!$E$4<Schedule_Inputs!$D$4),$C4/Schedule_Inputs!$D$4,0),0)))) -> 0 | AC4: =IF(Schedule_Inputs!$C$4="Blueprint",$C4*IF(25-Schedule_Inputs!$B$4=0,Assumptions!$B$21,IF(25-Schedule_Inputs!$B$4=1,Assumptions!$C$21,IF(25-Schedule_Inputs!$B$4=2,Assumptions!$D$21,0))),IF(Schedule_Inputs!$C$4="Launch",$C4*IF(25-Schedule_Inputs!$B$4=0,Assumptions!$B$22,IF(25-Schedule_Inputs!$B$4=1,Assumptions!$C$22,IF(25-Schedule_Inputs!$B$4=2,Assumptions!$D$22,IF(25-Schedule_Inputs!$B$4=3,Assumptions!$B$23,0)))),IF(Schedule_Inputs!$C$4="Office Setup",$C4*IF(25-Schedule_Inputs!$B$4=0,Assumptions!$B$24,IF(25-Schedule_Inputs!$B$4=1,Assumptions!$C$24,IF(25-Schedule_Inputs!$B$4=2,Assumptions!$D$24,0))),IF(OR(Schedule_Inputs!$C$4="Monthly",Schedule_Inputs!$C$4="Periodic"),IF(AND(25>=Schedule_Inputs!$B$4,MOD(25-Schedule_Inputs!$B$4,Schedule_Inputs!$E$4)=0,(25-Schedule_Inputs!$B$4)/Schedule_Inputs!$E$4<Schedule_Inputs!$D$4),$C4/Schedule_Inputs!$D$4,0),0)))) -> 0 | AD4: =IF(Schedule_Inputs!$C$4="Blueprint",$C4*IF(26-Schedule_Inputs!$B$4=0,Assumptions!$B$21,IF(26-Schedule_Inputs!$B$4=1,Assumptions!$C$21,IF(26-Schedule_Inputs!$B$4=2,Assumptions!$D$21,0))),IF(Schedule_Inputs!$C$4="Launch",$C4*IF(26-Schedule_Inputs!$B$4=0,Assumptions!$B$22,IF(26-Schedule_Inputs!$B$4=1,Assumptions!$C$22,IF(26-Schedule_Inputs!$B$4=2,Assumptions!$D$22,IF(26-Schedule_Inputs!$B$4=3,Assumptions!$B$23,0)))),IF(Schedule_Inputs!$C$4="Office Setup",$C4*IF(26-Schedule_Inputs!$B$4=0,Assumptions!$B$24,IF(26-Schedule_Inputs!$B$4=1,Assumptions!$C$24,IF(26-Schedule_Inputs!$B$4=2,Assumptions!$D$24,0))),IF(OR(Schedule_Inputs!$C$4="Monthly",Schedule_Inputs!$C$4="Periodic"),IF(AND(26>=Schedule_Inputs!$B$4,MOD(26-Schedule_Inputs!$B$4,Schedule_Inputs!$E$4)=0,(26-Schedule_Inputs!$B$4)/Schedule_Inputs!$E$4<Schedule_Inputs!$D$4),$C4/Schedule_Inputs!$D$4,0),0)))) -> 0 | AE4: =IF(Schedule_Inputs!$C$4="Blueprint",$C4*IF(27-Schedule_Inputs!$B$4=0,Assumptions!$B$21,IF(27-Schedule_Inputs!$B$4=1,Assumptions!$C$21,IF(27-Schedule_Inputs!$B$4=2,Assumptions!$D$21,0))),IF(Schedule_Inputs!$C$4="Launch",$C4*IF(27-Schedule_Inputs!$B$4=0,Assumptions!$B$22,IF(27-Schedule_Inputs!$B$4=1,Assumptions!$C$22,IF(27-Schedule_Inputs!$B$4=2,Assumptions!$D$22,IF(27-Schedule_Inputs!$B$4=3,Assumptions!$B$23,0)))),IF(Schedule_Inputs!$C$4="Office Setup",$C4*IF(27-Schedule_Inputs!$B$4=0,Assumptions!$B$24,IF(27-Schedule_Inputs!$B$4=1,Assumptions!$C$24,IF(27-Schedule_Inputs!$B$4=2,Assumptions!$D$24,0))),IF(OR(Schedule_Inputs!$C$4="Monthly",Schedule_Inputs!$C$4="Periodic"),IF(AND(27>=Schedule_Inputs!$B$4,MOD(27-Schedule_Inputs!$B$4,Schedule_Inputs!$E$4)=0,(27-Schedule_Inputs!$B$4)/Schedule_Inputs!$E$4<Schedule_Inputs!$D$4),$C4/Schedule_Inputs!$D$4,0),0)))) -> 0 | AF4: =IF(Schedule_Inputs!$C$4="Blueprint",$C4*IF(28-Schedule_Inputs!$B$4=0,Assumptions!$B$21,IF(28-Schedule_Inputs!$B$4=1,Assumptions!$C$21,IF(28-Schedule_Inputs!$B$4=2,Assumptions!$D$21,0))),IF(Schedule_Inputs!$C$4="Launch",$C4*IF(28-Schedule_Inputs!$B$4=0,Assumptions!$B$22,IF(28-Schedule_Inputs!$B$4=1,Assumptions!$C$22,IF(28-Schedule_Inputs!$B$4=2,Assumptions!$D$22,IF(28-Schedule_Inputs!$B$4=3,Assumptions!$B$23,0)))),IF(Schedule_Inputs!$C$4="Office Setup",$C4*IF(28-Schedule_Inputs!$B$4=0,Assumptions!$B$24,IF(28-Schedule_Inputs!$B$4=1,Assumptions!$C$24,IF(28-Schedule_Inputs!$B$4=2,Assumptions!$D$24,0))),IF(OR(Schedule_Inputs!$C$4="Monthly",Schedule_Inputs!$C$4="Periodic"),IF(AND(28>=Schedule_Inputs!$B$4,MOD(28-Schedule_Inputs!$B$4,Schedule_Inputs!$E$4)=0,(28-Schedule_Inputs!$B$4)/Schedule_Inputs!$E$4<Schedule_Inputs!$D$4),$C4/Schedule_Inputs!$D$4,0),0)))) -> 0 | AG4: =IF(Schedule_Inputs!$C$4="Blueprint",$C4*IF(29-Schedule_Inputs!$B$4=0,Assumptions!$B$21,IF(29-Schedule_Inputs!$B$4=1,Assumptions!$C$21,IF(29-Schedule_Inputs!$B$4=2,Assumptions!$D$21,0))),IF(Schedule_Inputs!$C$4="Launch",$C4*IF(29-Schedule_Inputs!$B$4=0,Assumptions!$B$22,IF(29-Schedule_Inputs!$B$4=1,Assumptions!$C$22,IF(29-Schedule_Inputs!$B$4=2,Assumptions!$D$22,IF(29-Schedule_Inputs!$B$4=3,Assumptions!$B$23,0)))),IF(Schedule_Inputs!$C$4="Office Setup",$C4*IF(29-Schedule_Inputs!$B$4=0,Assumptions!$B$24,IF(29-Schedule_Inputs!$B$4=1,Assumptions!$C$24,IF(29-Schedule_Inputs!$B$4=2,Assumptions!$D$24,0))),IF(OR(Schedule_Inputs!$C$4="Monthly",Schedule_Inputs!$C$4="Periodic"),IF(AND(29>=Schedule_Inputs!$B$4,MOD(29-Schedule_Inputs!$B$4,Schedule_Inputs!$E$4)=0,(29-Schedule_Inputs!$B$4)/Schedule_Inputs!$E$4<Schedule_Inputs!$D$4),$C4/Schedule_Inputs!$D$4,0),0)))) -> 0 | AH4: =IF(Schedule_Inputs!$C$4="Blueprint",$C4*IF(30-Schedule_Inputs!$B$4=0,Assumptions!$B$21,IF(30-Schedule_Inputs!$B$4=1,Assumptions!$C$21,IF(30-Schedule_Inputs!$B$4=2,Assumptions!$D$21,0))),IF(Schedule_Inputs!$C$4="Launch",$C4*IF(30-Schedule_Inputs!$B$4=0,Assumptions!$B$22,IF(30-Schedule_Inputs!$B$4=1,Assumptions!$C$22,IF(30-Schedule_Inputs!$B$4=2,Assumptions!$D$22,IF(30-Schedule_Inputs!$B$4=3,Assumptions!$B$23,0)))),IF(Schedule_Inputs!$C$4="Office Setup",$C4*IF(30-Schedule_Inputs!$B$4=0,Assumptions!$B$24,IF(30-Schedule_Inputs!$B$4=1,Assumptions!$C$24,IF(30-Schedule_Inputs!$B$4=2,Assumptions!$D$24,0))),IF(OR(Schedule_Inputs!$C$4="Monthly",Schedule_Inputs!$C$4="Periodic"),IF(AND(30>=Schedule_Inputs!$B$4,MOD(30-Schedule_Inputs!$B$4,Schedule_Inputs!$E$4)=0,(30-Schedule_Inputs!$B$4)/Schedule_Inputs!$E$4<Schedule_Inputs!$D$4),$C4/Schedule_Inputs!$D$4,0),0)))) -> 0 | AI4: =IF(Schedule_Inputs!$C$4="Blueprint",$C4*IF(31-Schedule_Inputs!$B$4=0,Assumptions!$B$21,IF(31-Schedule_Inputs!$B$4=1,Assumptions!$C$21,IF(31-Schedule_Inputs!$B$4=2,Assumptions!$D$21,0))),IF(Schedule_Inputs!$C$4="Launch",$C4*IF(31-Schedule_Inputs!$B$4=0,Assumptions!$B$22,IF(31-Schedule_Inputs!$B$4=1,Assumptions!$C$22,IF(31-Schedule_Inputs!$B$4=2,Assumptions!$D$22,IF(31-Schedule_Inputs!$B$4=3,Assumptions!$B$23,0)))),IF(Schedule_Inputs!$C$4="Office Setup",$C4*IF(31-Schedule_Inputs!$B$4=0,Assumptions!$B$24,IF(31-Schedule_Inputs!$B$4=1,Assumptions!$C$24,IF(31-Schedule_Inputs!$B$4=2,Assumptions!$D$24,0))),IF(OR(Schedule_Inputs!$C$4="Monthly",Schedule_Inputs!$C$4="Periodic"),IF(AND(31>=Schedule_Inputs!$B$4,MOD(31-Schedule_Inputs!$B$4,Schedule_Inputs!$E$4)=0,(31-Schedule_Inputs!$B$4)/Schedule_Inputs!$E$4<Schedule_Inputs!$D$4),$C4/Schedule_Inputs!$D$4,0),0)))) -> 0 | AJ4: =IF(Schedule_Inputs!$C$4="Blueprint",$C4*IF(32-Schedule_Inputs!$B$4=0,Assumptions!$B$21,IF(32-Schedule_Inputs!$B$4=1,Assumptions!$C$21,IF(32-Schedule_Inputs!$B$4=2,Assumptions!$D$21,0))),IF(Schedule_Inputs!$C$4="Launch",$C4*IF(32-Schedule_Inputs!$B$4=0,Assumptions!$B$22,IF(32-Schedule_Inputs!$B$4=1,Assumptions!$C$22,IF(32-Schedule_Inputs!$B$4=2,Assumptions!$D$22,IF(32-Schedule_Inputs!$B$4=3,Assumptions!$B$23,0)))),IF(Schedule_Inputs!$C$4="Office Setup",$C4*IF(32-Schedule_Inputs!$B$4=0,Assumptions!$B$24,IF(32-Schedule_Inputs!$B$4=1,Assumptions!$C$24,IF(32-Schedule_Inputs!$B$4=2,Assumptions!$D$24,0))),IF(OR(Schedule_Inputs!$C$4="Monthly",Schedule_Inputs!$C$4="Periodic"),IF(AND(32>=Schedule_Inputs!$B$4,MOD(32-Schedule_Inputs!$B$4,Schedule_Inputs!$E$4)=0,(32-Schedule_Inputs!$B$4)/Schedule_Inputs!$E$4<Schedule_Inputs!$D$4),$C4/Schedule_Inputs!$D$4,0),0)))) -> 0 | AK4: =IF(Schedule_Inputs!$C$4="Blueprint",$C4*IF(33-Schedule_Inputs!$B$4=0,Assumptions!$B$21,IF(33-Schedule_Inputs!$B$4=1,Assumptions!$C$21,IF(33-Schedule_Inputs!$B$4=2,Assumptions!$D$21,0))),IF(Schedule_Inputs!$C$4="Launch",$C4*IF(33-Schedule_Inputs!$B$4=0,Assumptions!$B$22,IF(33-Schedule_Inputs!$B$4=1,Assumptions!$C$22,IF(33-Schedule_Inputs!$B$4=2,Assumptions!$D$22,IF(33-Schedule_Inputs!$B$4=3,Assumptions!$B$23,0)))),IF(Schedule_Inputs!$C$4="Office Setup",$C4*IF(33-Schedule_Inputs!$B$4=0,Assumptions!$B$24,IF(33-Schedule_Inputs!$B$4=1,Assumptions!$C$24,IF(33-Schedule_Inputs!$B$4=2,Assumptions!$D$24,0))),IF(OR(Schedule_Inputs!$C$4="Monthly",Schedule_Inputs!$C$4="Periodic"),IF(AND(33>=Schedule_Inputs!$B$4,MOD(33-Schedule_Inputs!$B$4,Schedule_Inputs!$E$4)=0,(33-Schedule_Inputs!$B$4)/Schedule_Inputs!$E$4<Schedule_Inputs!$D$4),$C4/Schedule_Inputs!$D$4,0),0)))) -> 0 | AL4: =IF(Schedule_Inputs!$C$4="Blueprint",$C4*IF(34-Schedule_Inputs!$B$4=0,Assumptions!$B$21,IF(34-Schedule_Inputs!$B$4=1,Assumptions!$C$21,IF(34-Schedule_Inputs!$B$4=2,Assumptions!$D$21,0))),IF(Schedule_Inputs!$C$4="Launch",$C4*IF(34-Schedule_Inputs!$B$4=0,Assumptions!$B$22,IF(34-Schedule_Inputs!$B$4=1,Assumptions!$C$22,IF(34-Schedule_Inputs!$B$4=2,Assumptions!$D$22,IF(34-Schedule_Inputs!$B$4=3,Assumptions!$B$23,0)))),IF(Schedule_Inputs!$C$4="Office Setup",$C4*IF(34-Schedule_Inputs!$B$4=0,Assumptions!$B$24,IF(34-Schedule_Inputs!$B$4=1,Assumptions!$C$24,IF(34-Schedule_Inputs!$B$4=2,Assumptions!$D$24,0))),IF(OR(Schedule_Inputs!$C$4="Monthly",Schedule_Inputs!$C$4="Periodic"),IF(AND(34>=Schedule_Inputs!$B$4,MOD(34-Schedule_Inputs!$B$4,Schedule_Inputs!$E$4)=0,(34-Schedule_Inputs!$B$4)/Schedule_Inputs!$E$4<Schedule_Inputs!$D$4),$C4/Schedule_Inputs!$D$4,0),0)))) -> 0 | AM4: =IF(Schedule_Inputs!$C$4="Blueprint",$C4*IF(35-Schedule_Inputs!$B$4=0,Assumptions!$B$21,IF(35-Schedule_Inputs!$B$4=1,Assumptions!$C$21,IF(35-Schedule_Inputs!$B$4=2,Assumptions!$D$21,0))),IF(Schedule_Inputs!$C$4="Launch",$C4*IF(35-Schedule_Inputs!$B$4=0,Assumptions!$B$22,IF(35-Schedule_Inputs!$B$4=1,Assumptions!$C$22,IF(35-Schedule_Inputs!$B$4=2,Assumptions!$D$22,IF(35-Schedule_Inputs!$B$4=3,Assumptions!$B$23,0)))),IF(Schedule_Inputs!$C$4="Office Setup",$C4*IF(35-Schedule_Inputs!$B$4=0,Assumptions!$B$24,IF(35-Schedule_Inputs!$B$4=1,Assumptions!$C$24,IF(35-Schedule_Inputs!$B$4=2,Assumptions!$D$24,0))),IF(OR(Schedule_Inputs!$C$4="Monthly",Schedule_Inputs!$C$4="Periodic"),IF(AND(35>=Schedule_Inputs!$B$4,MOD(35-Schedule_Inputs!$B$4,Schedule_Inputs!$E$4)=0,(35-Schedule_Inputs!$B$4)/Schedule_Inputs!$E$4<Schedule_Inputs!$D$4),$C4/Schedule_Inputs!$D$4,0),0)))) -> 0 | AN4: =IF(Schedule_Inputs!$C$4="Blueprint",$C4*IF(36-Schedule_Inputs!$B$4=0,Assumptions!$B$21,IF(36-Schedule_Inputs!$B$4=1,Assumptions!$C$21,IF(36-Schedule_Inputs!$B$4=2,Assumptions!$D$21,0))),IF(Schedule_Inputs!$C$4="Launch",$C4*IF(36-Schedule_Inputs!$B$4=0,Assumptions!$B$22,IF(36-Schedule_Inputs!$B$4=1,Assumptions!$C$22,IF(36-Schedule_Inputs!$B$4=2,Assumptions!$D$22,IF(36-Schedule_Inputs!$B$4=3,Assumptions!$B$23,0)))),IF(Schedule_Inputs!$C$4="Office Setup",$C4*IF(36-Schedule_Inputs!$B$4=0,Assumptions!$B$24,IF(36-Schedule_Inputs!$B$4=1,Assumptions!$C$24,IF(36-Schedule_Inputs!$B$4=2,Assumptions!$D$24,0))),IF(OR(Schedule_Inputs!$C$4="Monthly",Schedule_Inputs!$C$4="Periodic"),IF(AND(36>=Schedule_Inputs!$B$4,MOD(36-Schedule_Inputs!$B$4,Schedule_Inputs!$E$4)=0,(36-Schedule_Inputs!$B$4)/Schedule_Inputs!$E$4<Schedule_Inputs!$D$4),$C4/Schedule_Inputs!$D$4,0),0)))) -> 0
