Workbook
Name afadrei: Investitionsplan!$H$38
Name afaeins: Investitionsplan!$D$38
Name afavier: Investitionsplan!$J$38
Name afazwei: Investitionsplan!$F$38
Name gj: 'Infos vor dem Start'!$A$13
Name gwg: Parameter!$A$12
Name gwgeins: Investitionsplan!$D$35
Name kapges: 'Infos vor dem Start'!$A$19
Name Monat: 'Infos vor dem Start'!$A$11
Name rechnung: 'Infos vor dem Start'!$A$15
Name USt: Parameter!$A$2
Name USt1neu: Parameter!$B$2
Name USteins: Parameter!$B$2
Name USterm: Parameter!$A$3
Name UStermeins: Parameter!$B$3
Name VSt: Parameter!$A$4
Name VSteins: Parameter!$B$4
Name VSterm: Parameter!$A$5
Name VStermeins: Parameter!$B$5
Name VStWE: Parameter!$A$6
Name VStWEeins: Parameter!$B$6

Sheet Infos vor dem Start
A1: Sehr geehrte Gründerin, sehr geehrter Gründer,
A3: vielen Dank, dass Sie das Finanztool der IHK Köln benutzen! Zunächst ein paar Informationen zur Bedienung:
A4: Wenn Sie nicht im Januar gründen, beginnen Sie bitte mit Ihren Eintragungen im ersten Jahr mit dem Monat, in dem Sie starten möchten. Insgesamt stehen vier Jahre als Planungshorizont zur Verfügung, davon sollten mindestens drei Jahre monatsgenau geplant werden. Tragen Sie Ihren ersten Monat zudem in das Eingabefeld weiter unten ein.
B6: Zellen, in die Sie Werte eintragen können, sind grün gekennzeichnet. Alle anderen Zellen sind schreibgeschützt.
B8: Einige Zellen haben wir mit Erläuterungen versehen - diese erkennen Sie an dem roten Dreieck rechts oben. Sie können sie lesen, wenn Sie mit dem Mauszeiger auf die entsprechende Zelle gehen.
A10: Außerdem bitten wir Sie um einige Angaben, um Ihnen die Arbeit zu erleichtern:
A11: 9 | B11: Ihr erster Gründungsmonat: Bitte geben Sie "1" ein für Januar, "2" für Februar usw. Beginnen Sie Ihre Einträge in der Tabelle bitte auch im entsprechenden Monat. Bitte lassen Sie dieses Feld nicht leer!
A13: 2026 | B13: Ihr Gründungsjahr: bitte ändern, falls abweichend
A15: x | B15: Wenn Sie gegen Rechnung liefern oder leisten, tragen Sie hier bitte ein "x" ein - der Zahlungseingang wird dann im nächsten Monat berücksichtigt. Bei Zug-um-Zug-Geschäften (Barzahlung, Vorkasse, Lastschrift o.ä.) lassen Sie das Feld bitte leer.
A17: x | B17: Wenn Sie Umsatzsteuer in Rechnung stellen werden, tragen Sie hier bitte ein "x" ein, sonst lassen Sie das Feld bitte leer. Die Berechnungen gehen nicht von einer Dauerfristverlängerung aus.
B19: Wenn Sie eine Kapitalgesellschaft (AG, GmbH, UG (haftungsbeschränkt) oder Ltd.) gründen, tragen Sie hier bitte ein "x" ein, sonst lassen Sie das Feld bitte leer.
A21: Wir stellen Ihnen hiermit unentgeltlich eine passwortgeschützte Datei in Excel zum Download zur Verfügung. Alle Änderungen daran,
A22: inbesondere Passwortaufhebung, Seiteneinrichtung und Konvertierungen in andere Formate erfolgen auf eigenes Risiko.
A23: Für alle daraus resultierenden Folgen, wie Ungenauigkeiten und Fehler der Anwendung, übernehmen wir keine Haftung.
A24: Wenn Sie Fragen, Wünsche oder andere Anliegen haben oder uns einfach mitteilen möchten, was Ihnen noch fehlt, schreiben Sie uns unter
A25: finanztool@koeln.ihk.de
A26: Bei Ihrem Vorhaben wünschen wir Ihnen viel Erfolg!
A28: Industrie- und Handelskammer zu Köln
A29: Ihr Team Beratung und Service

Sheet Umsatzplan Dienstleistungen
A1: Geplante Dienstleistungsumsätze | C1: =IF('Infos vor dem Start'!A17="x","EUR pro Leistungseinheit (netto)","EUR pro Leistungseinheit (brutto)") -> EUR pro Leistungseinheit (netto) | G1: Januar | H1: Februar | I1: März | J1: April | K1: Mai | L1: Juni | M1: Juli | N1: August | O1: September | P1: Oktober | Q1: November | R1: Dezember | S1: =+gj -> 2026 | T1: =+G1 -> Januar | U1: =+H1 -> Februar | V1: =+I1 -> März | W1: =+J1 -> April | X1: =+K1 -> Mai | Y1: =+L1 -> Juni | Z1: =+M1 -> Juli | AA1: =+N1 -> August | ... AE1: =+R1 -> Dezember | AF1: =+gj+1 -> 2027 | AG1: =+T1 -> Januar | AH1: =+U1 -> Februar | AI1: =+V1 -> März | AJ1: =+W1 -> April | AK1: =+X1 -> Mai | AL1: =+Y1 -> Juni | AM1: =+Z1 -> Juli | AN1: =+AA1 -> August | ... AR1: =+AE1 -> Dezember | AS1: =+gj+2 -> 2028 | AT1: =+AG1 -> Januar | AU1: =+AH1 -> Februar | AV1: =+AI1 -> März | AW1: =+AJ1 -> April | AX1: =+AK1 -> Mai | AY1: =+AL1 -> Juni | AZ1: =+AM1 -> Juli | BA1: =+AN1 -> August | ... BE1: =+AR1 -> Dezember | BF1: =+gj+3 -> 2029
C2: =+gj -> 2026 | D2: =+C2+1 -> 2027 | E2: =+D2+1 -> 2028 | F2: =+E2+1 -> 2029
A3: Paket 1 | C3: 18000 | G3: 0 | H3: 0 | I3: 0 | J3: 0 | K3: 0 | L3: 0 | M3: 0 | N3: 0 | O3: 0 | P3: 0 | Q3: 0 | R3: 1 | S3: =SUM(G3:R3) -> 1 | T3: =P3 -> 0 | U3: =T3*1.05 -> 0 | V3: =U3*1.05 -> 0 | W3: =V3*1.05 -> 0 | X3: =W3*1.05 -> 0 | Y3: =X3*1.05 -> 0 | Z3: =Y3*1.05 -> 0 | AA3: =Z3*1.05 -> 0 | AB3: =AA3*1.05 -> 0 | ... AE3: =AD3*1.05 -> 0 | AF3: =SUM(T3:AE3) -> 0 | AG3: =AC3 -> 0 | AH3: =AG3*1.05 -> 0 | AI3: =AH3*1.05 -> 0 | AJ3: =AI3*1.05 -> 0 | AK3: =AJ3*1.05 -> 0 | AL3: =AK3*1.05 -> 0 | AM3: =AL3*1.05 -> 0 | AN3: =AM3*1.05 -> 0 | AO3: 0 | AP3: 0 | AQ3: 0 | AR3: 0 | AS3: =SUM(AG3:AR3) -> 0 | BF3: =SUM(AT3:BE3) -> 0
A4: Paket 2 | C4: 29500 | G4: 0 | H4: 0 | I4: 0 | J4: 0 | K4: 0 | L4: 0 | M4: 0 | N4: 0 | O4: 0 | P4: 0 | Q4: 0 | R4: 0 | S4: =SUM(G4:R4) -> 0 | T4: =P4 -> 0 | U4: =T4*1.05 -> 0 | V4: =U4*1.05 -> 0 | W4: =V4*1.05 -> 0 | X4: =W4*1.05 -> 0 | Y4: =X4*1.05 -> 0 | Z4: =Y4*1.05 -> 0 | AA4: =Z4*1.05 -> 0 | AB4: =AA4*1.05 -> 0 | ... AE4: =AD4*1.05 -> 0 | AF4: =SUM(T4:AE4) -> 0 | AG4: =AC4 -> 0 | AH4: =AG4*1.05 -> 0 | AI4: =AH4*1.05 -> 0 | AJ4: =AI4*1.05 -> 0 | AK4: =AJ4*1.05 -> 0 | AL4: =AK4*1.05 -> 0 | AM4: =AL4*1.05 -> 0 | AN4: =AM4*1.05 -> 0 | AO4: 0 | AP4: 0 | AQ4: 0 | AR4: 0 | AS4: =SUM(AG4:AR4) -> 0 | BF4: =SUM(AT4:BE4) -> 0
A5: Paket 3 | C5: 14000 | G5: 0 | H5: 0 | I5: 0 | J5: 0 | K5: 0 | L5: 0 | M5: 0 | N5: 0 | O5: 0 | P5: 1 | Q5: 0 | R5: 0 | S5: =SUM(G5:R5) -> 1 | T5: =P5 -> 1 | U5: =T5*1.05 -> 1.05 | V5: =U5*1.05 -> 1.1025 | W5: =V5*1.05 -> 1.157625 | X5: =W5*1.05 -> 1.2155063 | Y5: =X5*1.05 -> 1.2762816 | Z5: =Y5*1.05 -> 1.3400956 | AA5: =Z5*1.05 -> 1.4071004 | AB5: =AA5*1.05 -> 1.4774554 | ... AE5: =AD5*1.05 -> 1.7103394 | AF5: =SUM(T5:AE5) -> 15.917127 | AG5: =AC5 -> 1.5513282 | AH5: =AG5*1.05 -> 1.6288946 | AI5: =AH5*1.05 -> 1.7103394 | AJ5: =AI5*1.05 -> 1.7958563 | AK5: =AJ5*1.05 -> 1.8856491 | AL5: =AK5*1.05 -> 1.9799316 | AM5: =AL5*1.05 -> 2.0789282 | AN5: =AM5*1.05 -> 2.1828746 | AO5: 0 | AP5: 0 | AQ5: 0 | AR5: 0 | AS5: =SUM(AG5:AR5) -> 14.813802 | BF5: =SUM(AT5:BE5) -> 0
G6: 0 | H6: 0 | I6: 0 | J6: 0 | K6: 0 | L6: 0 | M6: 0 | N6: 0 | O6: 0 | P6: 0 | Q6: 0 | R6: 0 | S6: =SUM(G6:R6) -> 0 | T6: =P6 -> 0 | U6: =T6*1.1 -> 0 | V6: =U6*1.1 -> 0 | W6: =V6*1.1 -> 0 | X6: =W6*1.1 -> 0 | Y6: =X6*1.1 -> 0 | Z6: =Y6*1.1 -> 0 | AA6: =Z6*1.1 -> 0 | AB6: =AA6*1.1 -> 0 | ... AE6: =AD6*1.1 -> 0 | AF6: =SUM(T6:AE6) -> 0 | AG6: =AC6 -> 0 | AH6: =AG6*1.05 -> 0 | AI6: =AH6*1.05 -> 0 | AJ6: =AI6*1.05 -> 0 | AK6: =AJ6*1.05 -> 0 | AL6: =AK6*1.05 -> 0 | AM6: =AL6*1.05 -> 0 | AN6: =AM6*1.05 -> 0 | AO6: 0 | AP6: 0 | AQ6: 0 | AR6: 0 | AS6: =SUM(AG6:AR6) -> 0 | BF6: =SUM(AT6:BE6) -> 0
G7: 0 | H7: 0 | I7: 0 | J7: 0 | K7: 0 | L7: 0 | M7: 0 | N7: 0 | O7: 0 | P7: 0 | Q7: 0 | R7: 0 | S7: =SUM(G7:R7) -> 0 | T7: =P7 -> 0 | U7: =T7*1.1 -> 0 | V7: =U7*1.1 -> 0 | W7: =V7*1.1 -> 0 | X7: =W7*1.1 -> 0 | Y7: =X7*1.1 -> 0 | Z7: =Y7*1.1 -> 0 | AA7: =Z7*1.1 -> 0 | AB7: =AA7*1.1 -> 0 | ... AE7: =AD7*1.1 -> 0 | AF7: =SUM(T7:AE7) -> 0 | AG7: =AC7 -> 0 | AH7: =AG7*1.05 -> 0 | AI7: =AH7*1.05 -> 0 | AJ7: =AI7*1.05 -> 0 | AK7: =AJ7*1.05 -> 0 | AL7: =AK7*1.05 -> 0 | AM7: =AL7*1.05 -> 0 | AN7: =AM7*1.05 -> 0 | AO7: 0 | AP7: 0 | AQ7: 0 | AR7: 0 | AS7: =SUM(AG7:AR7) -> 0 | BF7: =SUM(AT7:BE7) -> 0
G8: 0 | H8: 0 | I8: 0 | J8: 0 | K8: 0 | L8: 0 | M8: 0 | N8: 0 | O8: 0 | P8: 0 | Q8: 0 | R8: 0 | S8: =SUM(G8:R8) -> 0 | T8: =R8 -> 0 | U8: =S8 -> 0 | V8: =T8 -> 0 | W8: =U8 -> 0 | X8: =V8 -> 0 | Y8: =W8 -> 0 | Z8: =X8 -> 0 | AA8: =Y8 -> 0 | ... AE8: =AC8 -> 0 | AF8: =SUM(T8:AE8) -> 0 | AG8: 0 | AH8: 0 | AI8: 0 | AJ8: 0 | AK8: 0 | AL8: 0 | AM8: 0 | AN8: 0 | AO8: 0 | AP8: 0 | AQ8: 0 | AR8: 0 | AS8: =SUM(AG8:AR8) -> 0 | BF8: =SUM(AT8:BE8) -> 0
S9: =SUM(G9:R9) -> 0 | AF9: =SUM(T9:AE9) -> 0 | AS9: =SUM(AG9:AR9) -> 0 | BF9: =SUM(AT9:BE9) -> 0
S10: =SUM(G10:R10) -> 0 | AF10: =SUM(T10:AE10) -> 0 | AS10: =SUM(AG10:AR10) -> 0 | BF10: =SUM(AT10:BE10) -> 0
S11: =SUM(G11:R11) -> 0 | AF11: =SUM(T11:AE11) -> 0 | AS11: =SUM(AG11:AR11) -> 0 | BF11: =SUM(AT11:BE11) -> 0
S12: =SUM(G12:R12) -> 0 | AF12: =SUM(T12:AE12) -> 0 | AS12: =SUM(AG12:AR12) -> 0 | BF12: =SUM(AT12:BE12) -> 0
S13: =SUM(G13:R13) -> 0 | AF13: =SUM(T13:AE13) -> 0 | AS13: =SUM(AG13:AR13) -> 0 | BF13: =SUM(AT13:BE13) -> 0
S14: =SUM(G14:R14) -> 0 | AF14: =SUM(T14:AE14) -> 0 | AS14: =SUM(AG14:AR14) -> 0 | BF14: =SUM(AT14:BE14) -> 0
S15: =SUM(G15:R15) -> 0 | AF15: =SUM(T15:AE15) -> 0 | AS15: =SUM(AG15:AR15) -> 0 | BF15: =SUM(AT15:BE15) -> 0
S16: =SUM(G16:R16) -> 0 | AF16: =SUM(T16:AE16) -> 0 | AS16: =SUM(AG16:AR16) -> 0 | BF16: =SUM(AT16:BE16) -> 0
S17: =SUM(G17:R17) -> 0 | AF17: =SUM(T17:AE17) -> 0 | AS17: =SUM(AG17:AR17) -> 0 | BF17: =SUM(AT17:BE17) -> 0
S18: =SUM(G18:R18) -> 0 | AF18: =SUM(T18:AE18) -> 0 | AS18: =SUM(AG18:AR18) -> 0 | BF18: =SUM(AT18:BE18) -> 0
S19: =SUM(G19:R19) -> 0 | AF19: =SUM(T19:AE19) -> 0 | AS19: =SUM(AG19:AR19) -> 0 | BF19: =SUM(AT19:BE19) -> 0
S20: =SUM(G20:R20) -> 0 | AF20: =SUM(T20:AE20) -> 0 | AS20: =SUM(AG20:AR20) -> 0 | BF20: =SUM(AT20:BE20) -> 0
... S22: =SUM(G22:R22) -> 0 | AF22: =SUM(T22:AE22) -> 0 | AS22: =SUM(AG22:AR22) -> 0 | BF22: =SUM(AT22:BE22) -> 0
G23: =SUM(G3:G22) -> 0 | H23: =SUM(H3:H22) -> 0 | I23: =SUM(I3:I22) -> 0 | J23: =SUM(J3:J22) -> 0 | K23: =SUM(K3:K22) -> 0 | L23: =SUM(L3:L22) -> 0 | M23: =SUM(M3:M22) -> 0 | N23: =SUM(N3:N22) -> 0 | ... BF23: =SUM(BF3:BF22) -> 0
A24: =+A3 -> Paket 1 | G24: =+G3*$C3 -> 0 | H24: =+H3*$C3 -> 0 | I24: =+I3*$C3 -> 0 | J24: =+J3*$C3 -> 0 | K24: =+K3*$C3 -> 0 | L24: =+L3*$C3 -> 0 | M24: =+M3*$C3 -> 0 | N24: =+N3*$C3 -> 0 | ... R24: =+R3*$C3 -> 18000 | S24: =SUM(G24:R24) -> 18000 | T24: =+T3*$D3 -> 0 | U24: =+U3*$D3 -> 0 | V24: =+V3*$D3 -> 0 | W24: =+W3*$D3 -> 0 | X24: =+X3*$D3 -> 0 | Y24: =+Y3*$D3 -> 0 | Z24: =+Z3*$D3 -> 0 | AA24: =+AA3*$D3 -> 0 | ... AE24: =+AE3*$D3 -> 0 | AF24: =SUM(T24:AE24) -> 0 | AG24: =+AG3*$E3 -> 0 | AH24: =+AH3*$E3 -> 0 | AI24: =+AI3*$E3 -> 0 | AJ24: =+AJ3*$E3 -> 0 | AK24: =+AK3*$E3 -> 0 | AL24: =+AL3*$E3 -> 0 | AM24: =+AM3*$E3 -> 0 | AN24: =+AN3*$E3 -> 0 | ... AR24: =+AR3*$E3 -> 0 | AS24: =SUM(AG24:AR24) -> 0 | AT24: =+AT3*$F3 -> 0 | AU24: =+AU3*$F3 -> 0 | AV24: =+AV3*$F3 -> 0 | AW24: =+AW3*$F3 -> 0 | AX24: =+AX3*$F3 -> 0 | AY24: =+AY3*$F3 -> 0 | AZ24: =+AZ3*$F3 -> 0 | BA24: =+BA3*$F3 -> 0 | ... BE24: =+BE3*$F3 -> 0 | BF24: =SUM(AT24:BE24) -> 0
A25: =+A4 -> Paket 2 | G25: =+G4*$C4 -> 0 | H25: =+H4*$C4 -> 0 | I25: =+I4*$C4 -> 0 | J25: =+J4*$C4 -> 0 | K25: =+K4*$C4 -> 0 | L25: =+L4*$C4 -> 0 | M25: =+M4*$C4 -> 0 | N25: =+N4*$C4 -> 0 | ... R25: =+R4*$C4 -> 0 | S25: =SUM(G25:R25) -> 0 | T25: =+T4*$D4 -> 0 | U25: =+U4*$D4 -> 0 | V25: =+V4*$D4 -> 0 | W25: =+W4*$D4 -> 0 | X25: =+X4*$D4 -> 0 | Y25: =+Y4*$D4 -> 0 | Z25: =+Z4*$D4 -> 0 | AA25: =+AA4*$D4 -> 0 | ... AE25: =+AE4*$D4 -> 0 | AF25: =SUM(T25:AE25) -> 0 | AG25: =+AG4*$E4 -> 0 | AH25: =+AH4*$E4 -> 0 | AI25: =+AI4*$E4 -> 0 | AJ25: =+AJ4*$E4 -> 0 | AK25: =+AK4*$E4 -> 0 | AL25: =+AL4*$E4 -> 0 | AM25: =+AM4*$E4 -> 0 | AN25: =+AN4*$E4 -> 0 | ... AR25: =+AR4*$E4 -> 0 | AS25: =SUM(AG25:AR25) -> 0 | AT25: =+AT4*$F4 -> 0 | AU25: =+AU4*$F4 -> 0 | AV25: =+AV4*$F4 -> 0 | AW25: =+AW4*$F4 -> 0 | AX25: =+AX4*$F4 -> 0 | AY25: =+AY4*$F4 -> 0 | AZ25: =+AZ4*$F4 -> 0 | BA25: =+BA4*$F4 -> 0 | ... BE25: =+BE4*$F4 -> 0 | BF25: =SUM(AT25:BE25) -> 0
A26: =+A5 -> Paket 3 | G26: =+G5*$C5 -> 0 | H26: =+H5*$C5 -> 0 | I26: =+I5*$C5 -> 0 | J26: =+J5*$C5 -> 0 | K26: =+K5*$C5 -> 0 | L26: =+L5*$C5 -> 0 | M26: =+M5*$C5 -> 0 | N26: =+N5*$C5 -> 0 | ... R26: =+R5*$C5 -> 0 | S26: =SUM(G26:R26) -> 14000 | T26: =+T5*$D5 -> 0 | U26: =+U5*$D5 -> 0 | V26: =+V5*$D5 -> 0 | W26: =+W5*$D5 -> 0 | X26: =+X5*$D5 -> 0 | Y26: =+Y5*$D5 -> 0 | Z26: =+Z5*$D5 -> 0 | AA26: =+AA5*$D5 -> 0 | ... AE26: =+AE5*$D5 -> 0 | AF26: =SUM(T26:AE26) -> 0 | AG26: =+AG5*$E5 -> 0 | AH26: =+AH5*$E5 -> 0 | AI26: =+AI5*$E5 -> 0 | AJ26: =+AJ5*$E5 -> 0 | AK26: =+AK5*$E5 -> 0 | AL26: =+AL5*$E5 -> 0 | AM26: =+AM5*$E5 -> 0 | AN26: =+AN5*$E5 -> 0 | ... AR26: =+AR5*$E5 -> 0 | AS26: =SUM(AG26:AR26) -> 0 | AT26: =+AT5*$F5 -> 0 | AU26: =+AU5*$F5 -> 0 | AV26: =+AV5*$F5 -> 0 | AW26: =+AW5*$F5 -> 0 | AX26: =+AX5*$F5 -> 0 | AY26: =+AY5*$F5 -> 0 | AZ26: =+AZ5*$F5 -> 0 | BA26: =+BA5*$F5 -> 0 | ... BE26: =+BE5*$F5 -> 0 | BF26: =SUM(AT26:BE26) -> 0
A27: =+A6 -> 0 | G27: =+G6*$C6 -> 0 | H27: =+H6*$C6 -> 0 | I27: =+I6*$C6 -> 0 | J27: =+J6*$C6 -> 0 | K27: =+K6*$C6 -> 0 | L27: =+L6*$C6 -> 0 | M27: =+M6*$C6 -> 0 | N27: =+N6*$C6 -> 0 | ... R27: =+R6*$C6 -> 0 | S27: =SUM(G27:R27) -> 0 | T27: =+T6*$D6 -> 0 | U27: =+U6*$D6 -> 0 | V27: =+V6*$D6 -> 0 | W27: =+W6*$D6 -> 0 | X27: =+X6*$D6 -> 0 | Y27: =+Y6*$D6 -> 0 | Z27: =+Z6*$D6 -> 0 | AA27: =+AA6*$D6 -> 0 | ... AE27: =+AE6*$D6 -> 0 | AF27: =SUM(T27:AE27) -> 0 | AG27: =+AG6*$E6 -> 0 | AH27: =+AH6*$E6 -> 0 | AI27: =+AI6*$E6 -> 0 | AJ27: =+AJ6*$E6 -> 0 | AK27: =+AK6*$E6 -> 0 | AL27: =+AL6*$E6 -> 0 | AM27: =+AM6*$E6 -> 0 | AN27: =+AN6*$E6 -> 0 | ... AR27: =+AR6*$E6 -> 0 | AS27: =SUM(AG27:AR27) -> 0 | AT27: =+AT6*$F6 -> 0 | AU27: =+AU6*$F6 -> 0 | AV27: =+AV6*$F6 -> 0 | AW27: =+AW6*$F6 -> 0 | AX27: =+AX6*$F6 -> 0 | AY27: =+AY6*$F6 -> 0 | AZ27: =+AZ6*$F6 -> 0 | BA27: =+BA6*$F6 -> 0 | ... BE27: =+BE6*$F6 -> 0 | BF27: =SUM(AT27:BE27) -> 0
A28: =+A7 -> 0 | G28: =+G7*$C7 -> 0 | H28: =+H7*$C7 -> 0 | I28: =+I7*$C7 -> 0 | J28: =+J7*$C7 -> 0 | K28: =+K7*$C7 -> 0 | L28: =+L7*$C7 -> 0 | M28: =+M7*$C7 -> 0 | N28: =+N7*$C7 -> 0 | ... R28: =+R7*$C7 -> 0 | S28: =SUM(G28:R28) -> 0 | T28: =+T7*$D7 -> 0 | U28: =+U7*$D7 -> 0 | V28: =+V7*$D7 -> 0 | W28: =+W7*$D7 -> 0 | X28: =+X7*$D7 -> 0 | Y28: =+Y7*$D7 -> 0 | Z28: =+Z7*$D7 -> 0 | AA28: =+AA7*$D7 -> 0 | ... AE28: =+AE7*$D7 -> 0 | AF28: =SUM(T28:AE28) -> 0 | AG28: =+AG7*$E7 -> 0 | AH28: =+AH7*$E7 -> 0 | AI28: =+AI7*$E7 -> 0 | AJ28: =+AJ7*$E7 -> 0 | AK28: =+AK7*$E7 -> 0 | AL28: =+AL7*$E7 -> 0 | AM28: =+AM7*$E7 -> 0 | AN28: =+AN7*$E7 -> 0 | ... AR28: =+AR7*$E7 -> 0 | AS28: =SUM(AG28:AR28) -> 0 | AT28: =+AT7*$F7 -> 0 | AU28: =+AU7*$F7 -> 0 | AV28: =+AV7*$F7 -> 0 | AW28: =+AW7*$F7 -> 0 | AX28: =+AX7*$F7 -> 0 | AY28: =+AY7*$F7 -> 0 | AZ28: =+AZ7*$F7 -> 0 | BA28: =+BA7*$F7 -> 0 | ... BE28: =+BE7*$F7 -> 0 | BF28: =SUM(AT28:BE28) -> 0
A29: =+A8 -> 0 | G29: =+G8*$C8 -> 0 | H29: =+H8*$C8 -> 0 | I29: =+I8*$C8 -> 0 | J29: =+J8*$C8 -> 0 | K29: =+K8*$C8 -> 0 | L29: =+L8*$C8 -> 0 | M29: =+M8*$C8 -> 0 | N29: =+N8*$C8 -> 0 | ... R29: =+R8*$C8 -> 0 | S29: =SUM(G29:R29) -> 0 | T29: =+T8*$D8 -> 0 | U29: =+U8*$D8 -> 0 | V29: =+V8*$D8 -> 0 | W29: =+W8*$D8 -> 0 | X29: =+X8*$D8 -> 0 | Y29: =+Y8*$D8 -> 0 | Z29: =+Z8*$D8 -> 0 | AA29: =+AA8*$D8 -> 0 | ... AE29: =+AE8*$D8 -> 0 | AF29: =SUM(T29:AE29) -> 0 | AG29: =+AG8*$E8 -> 0 | AH29: =+AH8*$E8 -> 0 | AI29: =+AI8*$E8 -> 0 | AJ29: =+AJ8*$E8 -> 0 | AK29: =+AK8*$E8 -> 0 | AL29: =+AL8*$E8 -> 0 | AM29: =+AM8*$E8 -> 0 | AN29: =+AN8*$E8 -> 0 | ... AR29: =+AR8*$E8 -> 0 | AS29: =SUM(AG29:AR29) -> 0 | AT29: =+AT8*$F8 -> 0 | AU29: =+AU8*$F8 -> 0 | AV29: =+AV8*$F8 -> 0 | AW29: =+AW8*$F8 -> 0 | AX29: =+AX8*$F8 -> 0 | AY29: =+AY8*$F8 -> 0 | AZ29: =+AZ8*$F8 -> 0 | BA29: =+BA8*$F8 -> 0 | ... BE29: =+BE8*$F8 -> 0 | BF29: =SUM(AT29:BE29) -> 0
A30: =+A9 -> 0 | G30: =+G9*$C9 -> 0 | H30: =+H9*$C9 -> 0 | I30: =+I9*$C9 -> 0 | J30: =+J9*$C9 -> 0 | K30: =+K9*$C9 -> 0 | L30: =+L9*$C9 -> 0 | M30: =+M9*$C9 -> 0 | N30: =+N9*$C9 -> 0 | ... R30: =+R9*$C9 -> 0 | S30: =SUM(G30:R30) -> 0 | T30: =+T9*$D9 -> 0 | U30: =+U9*$D9 -> 0 | V30: =+V9*$D9 -> 0 | W30: =+W9*$D9 -> 0 | X30: =+X9*$D9 -> 0 | Y30: =+Y9*$D9 -> 0 | Z30: =+Z9*$D9 -> 0 | AA30: =+AA9*$D9 -> 0 | ... AE30: =+AE9*$D9 -> 0 | AF30: =SUM(T30:AE30) -> 0 | AG30: =+AG9*$E9 -> 0 | AH30: =+AH9*$E9 -> 0 | AI30: =+AI9*$E9 -> 0 | AJ30: =+AJ9*$E9 -> 0 | AK30: =+AK9*$E9 -> 0 | AL30: =+AL9*$E9 -> 0 | AM30: =+AM9*$E9 -> 0 | AN30: =+AN9*$E9 -> 0 | ... AR30: =+AR9*$E9 -> 0 | AS30: =SUM(AG30:AR30) -> 0 | AT30: =+AT9*$F9 -> 0 | AU30: =+AU9*$F9 -> 0 | AV30: =+AV9*$F9 -> 0 | AW30: =+AW9*$F9 -> 0 | AX30: =+AX9*$F9 -> 0 | AY30: =+AY9*$F9 -> 0 | AZ30: =+AZ9*$F9 -> 0 | BA30: =+BA9*$F9 -> 0 | ... BE30: =+BE9*$F9 -> 0 | BF30: =SUM(AT30:BE30) -> 0
A31: =+A10 -> 0 | G31: =+G10*$C10 -> 0 | H31: =+H10*$C10 -> 0 | I31: =+I10*$C10 -> 0 | J31: =+J10*$C10 -> 0 | K31: =+K10*$C10 -> 0 | L31: =+L10*$C10 -> 0 | M31: =+M10*$C10 -> 0 | N31: =+N10*$C10 -> 0 | ... R31: =+R10*$C10 -> 0 | S31: =SUM(G31:R31) -> 0 | T31: =+T10*$D10 -> 0 | U31: =+U10*$D10 -> 0 | V31: =+V10*$D10 -> 0 | W31: =+W10*$D10 -> 0 | X31: =+X10*$D10 -> 0 | Y31: =+Y10*$D10 -> 0 | Z31: =+Z10*$D10 -> 0 | AA31: =+AA10*$D10 -> 0 | ... AE31: =+AE10*$D10 -> 0 | AF31: =SUM(T31:AE31) -> 0 | AG31: =+AG10*$E10 -> 0 | AH31: =+AH10*$E10 -> 0 | AI31: =+AI10*$E10 -> 0 | AJ31: =+AJ10*$E10 -> 0 | AK31: =+AK10*$E10 -> 0 | AL31: =+AL10*$E10 -> 0 | AM31: =+AM10*$E10 -> 0 | AN31: =+AN10*$E10 -> 0 | ... AR31: =+AR10*$E10 -> 0 | AS31: =SUM(AG31:AR31) -> 0 | AT31: =+AT10*$F10 -> 0 | AU31: =+AU10*$F10 -> 0 | AV31: =+AV10*$F10 -> 0 | AW31: =+AW10*$F10 -> 0 | AX31: =+AX10*$F10 -> 0 | AY31: =+AY10*$F10 -> 0 | AZ31: =+AZ10*$F10 -> 0 | BA31: =+BA10*$F10 -> 0 | ... BE31: =+BE10*$F10 -> 0 | BF31: =SUM(AT31:BE31) -> 0
A32: =+A11 -> 0 | G32: =+G11*$C11 -> 0 | H32: =+H11*$C11 -> 0 | I32: =+I11*$C11 -> 0 | J32: =+J11*$C11 -> 0 | K32: =+K11*$C11 -> 0 | L32: =+L11*$C11 -> 0 | M32: =+M11*$C11 -> 0 | N32: =+N11*$C11 -> 0 | ... R32: =+R11*$C11 -> 0 | S32: =SUM(G32:R32) -> 0 | T32: =+T11*$D11 -> 0 | U32: =+U11*$D11 -> 0 | V32: =+V11*$D11 -> 0 | W32: =+W11*$D11 -> 0 | X32: =+X11*$D11 -> 0 | Y32: =+Y11*$D11 -> 0 | Z32: =+Z11*$D11 -> 0 | AA32: =+AA11*$D11 -> 0 | ... AE32: =+AE11*$D11 -> 0 | AF32: =SUM(T32:AE32) -> 0 | AG32: =+AG11*$E11 -> 0 | AH32: =+AH11*$E11 -> 0 | AI32: =+AI11*$E11 -> 0 | AJ32: =+AJ11*$E11 -> 0 | AK32: =+AK11*$E11 -> 0 | AL32: =+AL11*$E11 -> 0 | AM32: =+AM11*$E11 -> 0 | AN32: =+AN11*$E11 -> 0 | ... AR32: =+AR11*$E11 -> 0 | AS32: =SUM(AG32:AR32) -> 0 | AT32: =+AT11*$F11 -> 0 | AU32: =+AU11*$F11 -> 0 | AV32: =+AV11*$F11 -> 0 | AW32: =+AW11*$F11 -> 0 | AX32: =+AX11*$F11 -> 0 | AY32: =+AY11*$F11 -> 0 | AZ32: =+AZ11*$F11 -> 0 | BA32: =+BA11*$F11 -> 0 | ... BE32: =+BE11*$F11 -> 0 | BF32: =SUM(AT32:BE32) -> 0
A33: =+A12 -> 0 | G33: =+G12*$C12 -> 0 | H33: =+H12*$C12 -> 0 | I33: =+I12*$C12 -> 0 | J33: =+J12*$C12 -> 0 | K33: =+K12*$C12 -> 0 | L33: =+L12*$C12 -> 0 | M33: =+M12*$C12 -> 0 | N33: =+N12*$C12 -> 0 | ... R33: =+R12*$C12 -> 0 | S33: =SUM(G33:R33) -> 0 | T33: =+T12*$D12 -> 0 | U33: =+U12*$D12 -> 0 | V33: =+V12*$D12 -> 0 | W33: =+W12*$D12 -> 0 | X33: =+X12*$D12 -> 0 | Y33: =+Y12*$D12 -> 0 | Z33: =+Z12*$D12 -> 0 | AA33: =+AA12*$D12 -> 0 | ... AE33: =+AE12*$D12 -> 0 | AF33: =SUM(T33:AE33) -> 0 | AG33: =+AG12*$E12 -> 0 | AH33: =+AH12*$E12 -> 0 | AI33: =+AI12*$E12 -> 0 | AJ33: =+AJ12*$E12 -> 0 | AK33: =+AK12*$E12 -> 0 | AL33: =+AL12*$E12 -> 0 | AM33: =+AM12*$E12 -> 0 | AN33: =+AN12*$E12 -> 0 | ... AR33: =+AR12*$E12 -> 0 | AS33: =SUM(AG33:AR33) -> 0 | AT33: =+AT12*$F12 -> 0 | AU33: =+AU12*$F12 -> 0 | AV33: =+AV12*$F12 -> 0 | AW33: =+AW12*$F12 -> 0 | AX33: =+AX12*$F12 -> 0 | AY33: =+AY12*$F12 -> 0 | AZ33: =+AZ12*$F12 -> 0 | BA33: =+BA12*$F12 -> 0 | ... BE33: =+BE12*$F12 -> 0 | BF33: =SUM(AT33:BE33) -> 0
A34: =+A13 -> 0 | G34: =+G13*$C13 -> 0 | H34: =+H13*$C13 -> 0 | I34: =+I13*$C13 -> 0 | J34: =+J13*$C13 -> 0 | K34: =+K13*$C13 -> 0 | L34: =+L13*$C13 -> 0 | M34: =+M13*$C13 -> 0 | N34: =+N13*$C13 -> 0 | ... R34: =+R13*$C13 -> 0 | S34: =SUM(G34:R34) -> 0 | T34: =+T13*$D13 -> 0 | U34: =+U13*$D13 -> 0 | V34: =+V13*$D13 -> 0 | W34: =+W13*$D13 -> 0 | X34: =+X13*$D13 -> 0 | Y34: =+Y13*$D13 -> 0 | Z34: =+Z13*$D13 -> 0 | AA34: =+AA13*$D13 -> 0 | ... AE34: =+AE13*$D13 -> 0 | AF34: =SUM(T34:AE34) -> 0 | AG34: =+AG13*$E13 -> 0 | AH34: =+AH13*$E13 -> 0 | AI34: =+AI13*$E13 -> 0 | AJ34: =+AJ13*$E13 -> 0 | AK34: =+AK13*$E13 -> 0 | AL34: =+AL13*$E13 -> 0 | AM34: =+AM13*$E13 -> 0 | AN34: =+AN13*$E13 -> 0 | ... AR34: =+AR13*$E13 -> 0 | AS34: =SUM(AG34:AR34) -> 0 | AT34: =+AT13*$F13 -> 0 | AU34: =+AU13*$F13 -> 0 | AV34: =+AV13*$F13 -> 0 | AW34: =+AW13*$F13 -> 0 | AX34: =+AX13*$F13 -> 0 | AY34: =+AY13*$F13 -> 0 | AZ34: =+AZ13*$F13 -> 0 | BA34: =+BA13*$F13 -> 0 | ... BE34: =+BE13*$F13 -> 0 | BF34: =SUM(AT34:BE34) -> 0
A35: =+A14 -> 0 | G35: =+G14*$C14 -> 0 | H35: =+H14*$C14 -> 0 | I35: =+I14*$C14 -> 0 | J35: =+J14*$C14 -> 0 | K35: =+K14*$C14 -> 0 | L35: =+L14*$C14 -> 0 | M35: =+M14*$C14 -> 0 | N35: =+N14*$C14 -> 0 | ... R35: =+R14*$C14 -> 0 | S35: =SUM(G35:R35) -> 0 | T35: =+T14*$D14 -> 0 | U35: =+U14*$D14 -> 0 | V35: =+V14*$D14 -> 0 | W35: =+W14*$D14 -> 0 | X35: =+X14*$D14 -> 0 | Y35: =+Y14*$D14 -> 0 | Z35: =+Z14*$D14 -> 0 | AA35: =+AA14*$D14 -> 0 | ... AE35: =+AE14*$D14 -> 0 | AF35: =SUM(T35:AE35) -> 0 | AG35: =+AG14*$E14 -> 0 | AH35: =+AH14*$E14 -> 0 | AI35: =+AI14*$E14 -> 0 | AJ35: =+AJ14*$E14 -> 0 | AK35: =+AK14*$E14 -> 0 | AL35: =+AL14*$E14 -> 0 | AM35: =+AM14*$E14 -> 0 | AN35: =+AN14*$E14 -> 0 | ... AR35: =+AR14*$E14 -> 0 | AS35: =SUM(AG35:AR35) -> 0 | AT35: =+AT14*$F14 -> 0 | AU35: =+AU14*$F14 -> 0 | AV35: =+AV14*$F14 -> 0 | AW35: =+AW14*$F14 -> 0 | AX35: =+AX14*$F14 -> 0 | AY35: =+AY14*$F14 -> 0 | AZ35: =+AZ14*$F14 -> 0 | BA35: =+BA14*$F14 -> 0 | ... BE35: =+BE14*$F14 -> 0 | BF35: =SUM(AT35:BE35) -> 0
... A43: =+A22 -> 0 | G43: =+G22*$C22 -> 0 | H43: =+H22*$C22 -> 0 | I43: =+I22*$C22 -> 0 | J43: =+J22*$C22 -> 0 | K43: =+K22*$C22 -> 0 | L43: =+L22*$C22 -> 0 | M43: =+M22*$C22 -> 0 | N43: =+N22*$C22 -> 0 | ... R43: =+R22*$C22 -> 0 | S43: =SUM(G43:R43) -> 0 | T43: =+T22*$D22 -> 0 | U43: =+U22*$D22 -> 0 | V43: =+V22*$D22 -> 0 | W43: =+W22*$D22 -> 0 | X43: =+X22*$D22 -> 0 | Y43: =+Y22*$D22 -> 0 | Z43: =+Z22*$D22 -> 0 | AA43: =+AA22*$D22 -> 0 | ... AE43: =+AE22*$D22 -> 0 | AF43: =SUM(T43:AE43) -> 0 | AG43: =+AG22*$E22 -> 0 | AH43: =+AH22*$E22 -> 0 | AI43: =+AI22*$E22 -> 0 | AJ43: =+AJ22*$E22 -> 0 | AK43: =+AK22*$E22 -> 0 | AL43: =+AL22*$E22 -> 0 | AM43: =+AM22*$E22 -> 0 | AN43: =+AN22*$E22 -> 0 | ... AR43: =+AR22*$E22 -> 0 | AS43: =SUM(AG43:AR43) -> 0 | AT43: =+AT22*$F22 -> 0 | AU43: =+AU22*$F22 -> 0 | AV43: =+AV22*$F22 -> 0 | AW43: =+AW22*$F22 -> 0 | AX43: =+AX22*$F22 -> 0 | AY43: =+AY22*$F22 -> 0 | AZ43: =+AZ22*$F22 -> 0 | BA43: =+BA22*$F22 -> 0 | ... BE43: =+BE22*$F22 -> 0 | BF43: =SUM(AT43:BE43) -> 0
G44: =ROUND(SUM(G24:G43),0) -> 0 | H44: =ROUND(SUM(H24:H43),0) -> 0 | I44: =ROUND(SUM(I24:I43),0) -> 0 | J44: =ROUND(SUM(J24:J43),0) -> 0 | K44: =ROUND(SUM(K24:K43),0) -> 0 | L44: =ROUND(SUM(L24:L43),0) -> 0 | M44: =ROUND(SUM(M24:M43),0) -> 0 | N44: =ROUND(SUM(N24:N43),0) -> 0 | ... BF44: =ROUND(SUM(BF24:BF43),0) -> 0

Sheet Rentabilitätsvorschau
A1: =IF('Infos vor dem Start'!A17="x","Bitte Netto-Werte (ohne Umsatz- bzw. Vorsteuer) eintragen!","Bitte bei den Kosten Brutto-Werte (einschließlich Umsatzsteuer) eintragen!") -> Bitte Netto-Werte (ohne Umsatz- bzw. Vorsteuer) eintragen! | D1: =+'Umsatzplan Dienstleistungen'!G1 -> Januar | E1: =+'Umsatzplan Dienstleistungen'!H1 -> Februar | F1: =+'Umsatzplan Dienstleistungen'!I1 -> März | G1: =+'Umsatzplan Dienstleistungen'!J1 -> April | H1: =+'Umsatzplan Dienstleistungen'!K1 -> Mai | I1: =+'Umsatzplan Dienstleistungen'!L1 -> Juni | J1: =+'Umsatzplan Dienstleistungen'!M1 -> Juli | K1: =+'Umsatzplan Dienstleistungen'!N1 -> August | ... O1: =+'Umsatzplan Dienstleistungen'!R1 -> Dezember | P1: =+gj -> 2026 | Q1: =+'Umsatzplan Dienstleistungen'!T1 -> Januar | R1: =+'Umsatzplan Dienstleistungen'!U1 -> Februar | S1: =+'Umsatzplan Dienstleistungen'!V1 -> März | T1: =+'Umsatzplan Dienstleistungen'!W1 -> April | U1: =+'Umsatzplan Dienstleistungen'!X1 -> Mai | V1: =+'Umsatzplan Dienstleistungen'!Y1 -> Juni | W1: =+'Umsatzplan Dienstleistungen'!Z1 -> Juli | X1: =+'Umsatzplan Dienstleistungen'!AA1 -> August | ... AB1: =+'Umsatzplan Dienstleistungen'!AE1 -> Dezember | AC1: =+gj+1 -> 2027 | AD1: =+'Umsatzplan Dienstleistungen'!AG1 -> Januar | AE1: =+'Umsatzplan Dienstleistungen'!AH1 -> Februar | AF1: =+'Umsatzplan Dienstleistungen'!AI1 -> März | AG1: =+'Umsatzplan Dienstleistungen'!AJ1 -> April | AH1: =+'Umsatzplan Dienstleistungen'!AK1 -> Mai | AI1: =+'Umsatzplan Dienstleistungen'!AL1 -> Juni | AJ1: =+'Umsatzplan Dienstleistungen'!AM1 -> Juli | AK1: =+'Umsatzplan Dienstleistungen'!AN1 -> August | ... AO1: =+'Umsatzplan Dienstleistungen'!AR1 -> Dezember | AP1: =+gj+2 -> 2028 | AQ1: =+'Umsatzplan Dienstleistungen'!AT1 -> Januar | AR1: =+'Umsatzplan Dienstleistungen'!AU1 -> Februar | AS1: =+'Umsatzplan Dienstleistungen'!AV1 -> März | AT1: =+'Umsatzplan Dienstleistungen'!AW1 -> April | AU1: =+'Umsatzplan Dienstleistungen'!AX1 -> Mai | AV1: =+'Umsatzplan Dienstleistungen'!AY1 -> Juni | AW1: =+'Umsatzplan Dienstleistungen'!AZ1 -> Juli | AX1: =+'Umsatzplan Dienstleistungen'!BA1 -> August | ... BB1: =+'Umsatzplan Dienstleistungen'!BE1 -> Dezember | BC1: =+gj+3 -> 2029
A2: Umsatz Handel/Produktion
B3: =IF('Infos vor dem Start'!A17="x","Umsatz 19%","Umsatz") -> Umsatz 19% | P3: =SUM(D3:O3) -> 0 | AC3: =SUM(Q3:AB3) -> 0 | AP3: =SUM(AD3:AO3) -> 0 | BC3: =SUM(AQ3:BB3) -> 0
B4: =IF('Infos vor dem Start'!A17="x","Umsatz 7%","Umsatz") -> Umsatz 7% | D4: 0 | E4: 0 | F4: 0 | G4: 0 | H4: 0 | I4: 0 | J4: 0 | K4: 0 | L4: 0 | M4: 0 | N4: 0 | O4: 0 | P4: =SUM(D4:O4) -> 0 | AC4: =SUM(Q4:AB4) -> 0 | AP4: =SUM(AD4:AO4) -> 0 | BC4: =SUM(AQ4:BB4) -> 0
A5: =IF(+'Infos vor dem Start'!A17="x","Umsatz Dienstleistungen 19%","Umsatz Dienstleistungen") -> Umsatz Dienstleistungen 19% | D5: =+'Umsatzplan Dienstleistungen'!G44 -> 0 | E5: =+'Umsatzplan Dienstleistungen'!H44 -> 0 | F5: =+'Umsatzplan Dienstleistungen'!I44 -> 0 | G5: =+'Umsatzplan Dienstleistungen'!J44 -> 0 | H5: =+'Umsatzplan Dienstleistungen'!K44 -> 0 | I5: =+'Umsatzplan Dienstleistungen'!L44 -> 0 | J5: =+'Umsatzplan Dienstleistungen'!M44 -> 0 | K5: =+'Umsatzplan Dienstleistungen'!N44 -> 0 | ... O5: =+'Umsatzplan Dienstleistungen'!R44 -> 18000 | P5: =SUM(D5:O5) -> 32000 | Q5: =+'Umsatzplan Dienstleistungen'!T44 -> 0 | R5: =+'Umsatzplan Dienstleistungen'!U44 -> 0 | S5: =+'Umsatzplan Dienstleistungen'!V44 -> 0 | T5: =+'Umsatzplan Dienstleistungen'!W44 -> 0 | U5: =+'Umsatzplan Dienstleistungen'!X44 -> 0 | V5: =+'Umsatzplan Dienstleistungen'!Y44 -> 0 | W5: =+'Umsatzplan Dienstleistungen'!Z44 -> 0 | X5: =+'Umsatzplan Dienstleistungen'!AA44 -> 0 | ... AB5: =+'Umsatzplan Dienstleistungen'!AE44 -> 0 | AC5: =SUM(Q5:AB5) -> 0 | AD5: =+'Umsatzplan Dienstleistungen'!AG44 -> 0 | AE5: =+'Umsatzplan Dienstleistungen'!AH44 -> 0 | AF5: =+'Umsatzplan Dienstleistungen'!AI44 -> 0 | AG5: =+'Umsatzplan Dienstleistungen'!AJ44 -> 0 | AH5: =+'Umsatzplan Dienstleistungen'!AK44 -> 0 | AI5: =+'Umsatzplan Dienstleistungen'!AL44 -> 0 | AJ5: =+'Umsatzplan Dienstleistungen'!AM44 -> 0 | AK5: =+'Umsatzplan Dienstleistungen'!AN44 -> 0 | ... AO5: =+'Umsatzplan Dienstleistungen'!AR44 -> 0 | AP5: =SUM(AD5:AO5) -> 0 | AQ5: =+'Umsatzplan Dienstleistungen'!AT44 -> 0 | AR5: =+'Umsatzplan Dienstleistungen'!AU44 -> 0 | AS5: =+'Umsatzplan Dienstleistungen'!AV44 -> 0 | AT5: =+'Umsatzplan Dienstleistungen'!AW44 -> 0 | AU5: =+'Umsatzplan Dienstleistungen'!AX44 -> 0 | AV5: =+'Umsatzplan Dienstleistungen'!AY44 -> 0 | AW5: =+'Umsatzplan Dienstleistungen'!AZ44 -> 0 | AX5: =+'Umsatzplan Dienstleistungen'!BA44 -> 0 | ... BB5: =+'Umsatzplan Dienstleistungen'!BE44 -> 0 | BC5: =SUM(AQ5:BB5) -> 0
C6: Erlösschmälerungen (Skonto) | D6: =(+D3+D4+D5)*$B6 -> 0 | E6: =(+E3+E4+E5)*$B6 -> 0 | F6: =(+F3+F4+F5)*$B6 -> 0 | G6: =(+G3+G4+G5)*$B6 -> 0 | H6: =(+H3+H4+H5)*$B6 -> 0 | I6: =(+I3+I4+I5)*$B6 -> 0 | J6: =(+J3+J4+J5)*$B6 -> 0 | K6: =(+K3+K4+K5)*$B6 -> 0 | ... O6: =(+O3+O4+O5)*$B6 -> 0 | P6: =SUM(D6:O6) -> 0 | Q6: =(+Q3+Q4+Q5)*$B6 -> 0 | R6: =(+R3+R4+R5)*$B6 -> 0 | S6: =(+S3+S4+S5)*$B6 -> 0 | T6: =(+T3+T4+T5)*$B6 -> 0 | U6: =(+U3+U4+U5)*$B6 -> 0 | V6: =(+V3+V4+V5)*$B6 -> 0 | W6: =(+W3+W4+W5)*$B6 -> 0 | X6: =(+X3+X4+X5)*$B6 -> 0 | ... AB6: =(+AB3+AB4+AB5)*$B6 -> 0 | AC6: =SUM(Q6:AB6) -> 0 | AD6: =(+AD3+AD4+AD5)*$B6 -> 0 | AE6: =(+AE3+AE4+AE5)*$B6 -> 0 | AF6: =(+AF3+AF4+AF5)*$B6 -> 0 | AG6: =(+AG3+AG4+AG5)*$B6 -> 0 | AH6: =(+AH3+AH4+AH5)*$B6 -> 0 | AI6: =(+AI3+AI4+AI5)*$B6 -> 0 | AJ6: =(+AJ3+AJ4+AJ5)*$B6 -> 0 | AK6: =(+AK3+AK4+AK5)*$B6 -> 0 | ... AO6: =(+AO3+AO4+AO5)*$B6 -> 0 | AP6: =SUM(AD6:AO6) -> 0 | AQ6: =(+AQ3+AQ4+AQ5)*$B6 -> 0 | AR6: =(+AR3+AR4+AR5)*$B6 -> 0 | AS6: =(+AS3+AS4+AS5)*$B6 -> 0 | AT6: =(+AT3+AT4+AT5)*$B6 -> 0 | AU6: =(+AU3+AU4+AU5)*$B6 -> 0 | AV6: =(+AV3+AV4+AV5)*$B6 -> 0 | AW6: =(+AW3+AW4+AW5)*$B6 -> 0 | AX6: =(+AX3+AX4+AX5)*$B6 -> 0 | ... BB6: =(+BB3+BB4+BB5)*$B6 -> 0 | BC6: =SUM(AQ6:BB6) -> 0
A7: sonstige betriebliche Erträge | P7: =SUM(D7:O7) -> 0 | AC7: =SUM(Q7:AB7) -> 0 | AP7: =SUM(AD7:AO7) -> 0 | BC7: =SUM(AQ7:BB7) -> 0
A8: Wareneinkauf/Materialaufwand
B9: 0 | C9: pauschaler Wareneinsatz | E9: =(+D3+D4)*$B9 -> 0 | F9: =(+E3+E4)*$B9 -> 0 | G9: =(+F3+F4)*$B9 -> 0 | H9: =(+G3+G4)*$B9 -> 0 | I9: =(+H3+H4)*$B9 -> 0 | J9: =(+I3+I4)*$B9 -> 0 | K9: =(+J3+J4)*$B9 -> 0 | L9: =(+K3+K4)*$B9 -> 0 | ... O9: =(+N3+N4)*$B9 -> 0 | P9: =SUM(D9:O9) -> 0 | Q9: =(+O3+O4)*$B9 -> 0 | R9: =(+Q3+Q4)*$B9 -> 0 | S9: =(+R3+R4)*$B9 -> 0 | T9: =(+S3+S4)*$B9 -> 0 | U9: =(+T3+T4)*$B9 -> 0 | V9: =(+U3+U4)*$B9 -> 0 | W9: =(+V3+V4)*$B9 -> 0 | X9: =(+W3+W4)*$B9 -> 0 | Y9: =(+X3+X4)*$B9 -> 0 | ... AB9: =(+AA3+AA4)*$B9 -> 0 | AC9: =SUM(Q9:AB9) -> 0 | AD9: =(+AB3+AB4)*$B9 -> 0 | AE9: =(+AD3+AD4)*$B9 -> 0 | AF9: =(+AE3+AE4)*$B9 -> 0 | AG9: =(+AF3+AF4)*$B9 -> 0 | AH9: =(+AG3+AG4)*$B9 -> 0 | AI9: =(+AH3+AH4)*$B9 -> 0 | AJ9: =(+AI3+AI4)*$B9 -> 0 | AK9: =(+AJ3+AJ4)*$B9 -> 0 | AL9: =(+AK3+AK4)*$B9 -> 0 | ... AO9: =(+AN3+AN4)*$B9 -> 0 | AP9: =SUM(AD9:AO9) -> 0 | AQ9: =(+AO3+AO4)*$B9 -> 0 | AR9: =(+AQ3+AQ4)*$B9 -> 0 | AS9: =(+AR3+AR4)*$B9 -> 0 | AT9: =(+AS3+AS4)*$B9 -> 0 | AU9: =(+AT3+AT4)*$B9 -> 0 | AV9: =(+AU3+AU4)*$B9 -> 0 | AW9: =(+AV3+AV4)*$B9 -> 0 | AX9: =(+AW3+AW4)*$B9 -> 0 | AY9: =(+AX3+AX4)*$B9 -> 0 | ... BB9: =(+BA3+BA4)*$B9 -> 0 | BC9: =SUM(AQ9:BB9) -> 0
B10: Fremdleistungen | P10: =SUM(D10:O10) -> 0 | AC10: =SUM(Q10:AB10) -> 0 | AP10: =SUM(AD10:AO10) -> 0 | BC10: =SUM(AQ10:BB10) -> 0
B11: Wareneinkauf Saisongeschäft
B12: Warenlager-Erstausstattung und -aufstockung | D12: =IF(Monat=1,Investitionsplan!$C46,0) -> 0 | E12: =IF(Monat=2,Investitionsplan!$C46,0) -> 0 | F12: =IF(Monat=3,Investitionsplan!$C46,0) -> 0 | G12: =IF(Monat=4,Investitionsplan!$C46,0) -> 0 | H12: =IF(Monat=5,Investitionsplan!$C46,0) -> 0 | I12: =IF(Monat=6,Investitionsplan!$C46,0) -> 0 | J12: =IF(Monat=7,Investitionsplan!$C46,0) -> 0 | K12: =IF(Monat=8,Investitionsplan!$C46,0) -> 0 | L12: =IF(Monat=9,Investitionsplan!$C46,0) -> 0 | M12: =IF(Monat=10,Investitionsplan!$C46,0) -> 0 | N12: =IF(Monat=11,Investitionsplan!$C46,0) -> 0 | O12: =IF(Monat=12,Investitionsplan!$C46,0) -> 0 | P12: =SUM(D12:O12) -> 0 | Q12: =+Investitionsplan!E46 -> 0 | AC12: =SUM(Q12:AB12) -> 0 | AD12: =+Investitionsplan!G46 -> 0 | AP12: =SUM(AD12:AO12) -> 0 | AQ12: =+Investitionsplan!I46 -> 0 | BC12: =SUM(AQ12:BB12) -> 0
A13: Rohergebnis | D13: =+D3+D4+D5-D6+D7-D9-D10-D11-D12 -> 0 | E13: =+E3+E4+E5-E6+E7-E9-E10-E11-E12 -> 0 | F13: =+F3+F4+F5-F6+F7-F9-F10-F11-F12 -> 0 | G13: =+G3+G4+G5-G6+G7-G9-G10-G11-G12 -> 0 | H13: =+H3+H4+H5-H6+H7-H9-H10-H11-H12 -> 0 | I13: =+I3+I4+I5-I6+I7-I9-I10-I11-I12 -> 0 | J13: =+J3+J4+J5-J6+J7-J9-J10-J11-J12 -> 0 | K13: =+K3+K4+K5-K6+K7-K9-K10-K11-K12 -> 0 | ... BC13: =+BC3+BC4+BC5-BC6+BC7-BC9-BC10-BC11-BC12 -> 0
A14: Personalaufwand incl. Sozialabgaben (ca. 22%) | M14: 0 | N14: 0 | O14: 0 | P14: =SUM(D14:O14) -> 0 | Q14: 720 | R14: 720 | S14: 720 | T14: 720 | U14: 720 | V14: 720 | W14: 720 | X14: 720 | Y14: 720 | Z14: 720 | AA14: 720 | AB14: 720 | AC14: =SUM(Q14:AB14) -> 8640 | AD14: 0 | AE14: 0 | AF14: 0 | AG14: 0 | AH14: 0 | AI14: 0 | AJ14: 0 | AK14: 0 | AL14: 0 | AM14: 0 | AN14: 0 | AO14: 0 | AP14: =SUM(AD14:AO14) -> 0 | BC14: =SUM(AQ14:BB14) -> 0
A15: Abschreibungen | D15: =IF(Monat<=0,0,IF(Monat=1,ROUND(afaeins,0),)) -> 0 | E15: =IF(Monat=0,0,IF(Monat=2,ROUND(afaeins,0),IF(Monat<2,afaeins,0))) -> 0 | F15: =IF(Monat=0,0,IF(Monat=3,ROUND(afaeins,0),IF(Monat<3,afaeins,0))) -> 0 | G15: =IF(Monat=0,0,IF(Monat=4,ROUND(afaeins,0),IF(Monat<4,afaeins,0))) -> 0 | H15: =IF(Monat=0,0,IF(Monat=5,ROUND(afaeins,0),IF(Monat<5,afaeins,0))) -> 0 | I15: =IF(Monat=0,0,IF(Monat=6,ROUND(afaeins,0),IF(Monat<6,afaeins,0))) -> 0 | J15: =IF(Monat=0,0,IF(Monat=7,ROUND(afaeins,0),IF(Monat<7,afaeins,0))) -> 0 | K15: =IF(Monat=0,0,IF(Monat=8,ROUND(afaeins,0),IF(Monat<8,afaeins,0))) -> 0 | L15: =IF(Monat=0,0,IF(Monat=9,ROUND(afaeins,0),IF(Monat<9,afaeins,0))) -> 0 | M15: =IF(Monat=0,0,IF(Monat=10,ROUND(afaeins,0),IF(Monat<10,afaeins,0))) -> 0 | N15: =IF(Monat=0,0,IF(Monat=11,ROUND(afaeins,0),IF(Monat<11,afaeins,0))) -> 0 | O15: =IF(Monat=0,0,IF(Monat=11,ROUND(afaeins,0),IF(Monat<11,afaeins,0))) -> 0 | P15: =SUM(D15:O15) -> 0 | Q15: =+afazwei -> 0 | R15: =+afazwei -> 0 | S15: =+afazwei -> 0 | T15: =+afazwei -> 0 | U15: =+afazwei -> 0 | V15: =+afazwei -> 0 | W15: =+afazwei -> 0 | X15: =+afazwei -> 0 | ... AB15: =+afazwei -> 0 | AC15: =SUM(Q15:AB15) -> 0 | AD15: =+afadrei -> 0 | AE15: =+afadrei -> 0 | AF15: =+afadrei -> 0 | AG15: =+afadrei -> 0 | AH15: =+afadrei -> 0 | AI15: =+afadrei -> 0 | AJ15: =+afadrei -> 0 | AK15: =+afadrei -> 0 | ... AO15: =+afadrei -> 0 | AP15: =SUM(AD15:AO15) -> 0 | AQ15: =+afavier -> 0 | AR15: =+afavier -> 0 | AS15: =+afavier -> 0 | AT15: =+afavier -> 0 | AU15: =+afavier -> 0 | AV15: =+afavier -> 0 | AW15: =+afavier -> 0 | AX15: =+afavier -> 0 | ... BB15: =+afavier -> 0 | BC15: =SUM(AQ15:BB15) -> 0
A16: Sonstige betriebliche Aufwendungen
B17: Raumkosten (Miete, Nebenkosten, Reinigung etc.)
C18: Miete und Nebenkosten | D18: 0 | E18: 0 | F18: 0 | G18: 0 | H18: 0 | I18: 0 | J18: 0 | K18: 0 | L18: 0 | M18: 600 | N18: 600 | O18: 600 | P18: =SUM(D18:O18) -> 1800 | Q18: 600 | R18: 600 | S18: 600 | T18: 600 | U18: 600 | V18: 600 | W18: 600 | X18: 600 | Y18: 600 | Z18: 600 | AA18: 600 | AB18: 600 | AC18: =SUM(Q18:AB18) -> 7200 | AD18: 0 | AE18: 0 | AF18: 0 | AG18: 0 | AH18: 0 | AI18: 0 | AJ18: 0 | AK18: 0 | AL18: 0 | AM18: 0 | AN18: 0 | AO18: 0 | AP18: =SUM(AD18:AO18) -> 0 | BC18: =SUM(AQ18:BB18) -> 0
C19: Instandhaltung | D19: 0 | E19: 0 | F19: 0 | G19: 0 | H19: 0 | I19: 0 | J19: 0 | K19: 0 | L19: 0 | M19: 50 | N19: 50 | O19: 50 | P19: =SUM(D19:O19) -> 150 | Q19: 50 | R19: 50 | S19: 50 | T19: 50 | U19: 50 | V19: 50 | W19: 50 | X19: 50 | Y19: 50 | Z19: 50 | AA19: 50 | AB19: 50 | AC19: =SUM(Q19:AB19) -> 600 | AD19: 0 | AE19: 0 | AF19: 0 | AG19: 0 | AH19: 0 | AI19: 0 | AJ19: 0 | AK19: 0 | AL19: 0 | AM19: 0 | AN19: 0 | AO19: 0 | AP19: =SUM(AD19:AO19) -> 0 | BC19: =SUM(AQ19:BB19) -> 0
B20: Telefon, Fax | D20: 0 | E20: 0 | F20: 0 | G20: 0 | H20: 0 | I20: 0 | J20: 0 | K20: 0 | L20: 0 | M20: 100 | N20: 100 | O20: 100 | P20: =SUM(D20:O20) -> 300 | Q20: 100 | R20: 100 | S20: 100 | T20: 100 | U20: 100 | V20: 100 | W20: 100 | X20: 100 | Y20: 100 | Z20: 100 | AA20: 100 | AB20: 100 | AC20: =SUM(Q20:AB20) -> 1200 | AD20: 0 | AE20: 0 | AF20: 0 | AG20: 0 | AH20: 0 | AI20: 0 | AJ20: 0 | AK20: 0 | AL20: 0 | AM20: 0 | AN20: 0 | AO20: 0 | AP20: =SUM(AD20:AO20) -> 0 | BC20: =SUM(AQ20:BB20) -> 0
B21: Kfz-Kosten
C22: Kfz-Versicherungen | D22: 0 | E22: 0 | F22: 0 | G22: 0 | H22: 0 | I22: 0 | J22: 0 | K22: 0 | L22: 0 | M22: 0 | N22: 0 | O22: 0 | P22: =SUM(D22:O22) -> 0 | Q22: 0 | R22: 0 | S22: 0 | T22: 0 | U22: 0 | V22: 0 | W22: 0 | X22: 0 | Y22: 0 | Z22: 0 | AA22: 0 | AB22: 0 | AC22: =SUM(Q22:AB22) -> 0 | AD22: 0 | AE22: 0 | AF22: 0 | AG22: 0 | AH22: 0 | AI22: 0 | AJ22: 0 | AK22: 0 | AL22: 0 | AM22: 0 | AN22: 0 | AO22: 0 | AP22: =SUM(AD22:AO22) -> 0 | BC22: =SUM(AQ22:BB22) -> 0
C23: Wartung und Reparatur | D23: 0 | E23: 0 | F23: 0 | G23: 0 | H23: 0 | I23: 0 | J23: 0 | K23: 0 | L23: 0 | M23: 0 | N23: 0 | O23: 0 | P23: =SUM(D23:O23) -> 0 | Q23: 0 | R23: 0 | S23: 0 | T23: 0 | U23: 0 | V23: 0 | W23: 0 | X23: 0 | Y23: 0 | Z23: 0 | AA23: 0 | AB23: 0 | AC23: =SUM(Q23:AB23) -> 0 | AD23: 0 | AE23: 0 | AF23: 0 | AG23: 0 | AH23: 0 | AI23: 0 | AJ23: 0 | AK23: 0 | AL23: 0 | AM23: 0 | AN23: 0 | AO23: 0 | AP23: =SUM(AD23:AO23) -> 0 | BC23: =SUM(AQ23:BB23) -> 0
C24: Leasing (nur Kfz) | D24: 0 | E24: 0 | F24: 0 | G24: 0 | H24: 0 | I24: 0 | J24: 0 | K24: 0 | L24: 0 | M24: 0 | N24: 0 | O24: 0 | P24: =SUM(D24:O24) -> 0 | Q24: 0 | R24: 0 | S24: 0 | T24: 0 | U24: 0 | V24: 0 | W24: 0 | X24: 0 | Y24: 0 | Z24: 0 | AA24: 0 | AB24: 0 | AC24: =SUM(Q24:AB24) -> 0 | AD24: 0 | AE24: 0 | AF24: 0 | AG24: 0 | AH24: 0 | AI24: 0 | AJ24: 0 | AK24: 0 | AL24: 0 | AM24: 0 | AN24: 0 | AO24: 0 | AP24: =SUM(AD24:AO24) -> 0 | BC24: =SUM(AQ24:BB24) -> 0
C25: Betriebskosten | D25: 0 | E25: 0 | F25: 0 | G25: 0 | H25: 0 | I25: 0 | J25: 0 | K25: 0 | L25: 0 | M25: 0 | N25: 0 | O25: 0 | P25: =SUM(D25:O25) -> 0 | Q25: 0 | R25: 0 | S25: 0 | T25: 0 | U25: 0 | V25: 0 | W25: 0 | X25: 0 | Y25: 0 | Z25: 0 | AA25: 0 | AB25: 0 | AC25: =SUM(Q25:AB25) -> 0 | AD25: =AB25*1.05 -> 0 | AE25: =AC25*1.05 -> 0 | AF25: =AD25*1.05 -> 0 | AG25: =AE25*1.05 -> 0 | AH25: =AF25*1.05 -> 0 | AI25: =AG25*1.05 -> 0 | AJ25: =AH25*1.05 -> 0 | AK25: =AI25*1.05 -> 0 | AL25: =AJ25*1.05 -> 0 | AM25: 0 | AN25: 0 | AO25: 0 | AP25: =SUM(AD25:AO25) -> 0 | BC25: =SUM(AQ25:BB25) -> 0
B26: Reise- und Bewirtungskosten | D26: 0 | E26: 0 | F26: 0 | G26: 0 | H26: 0 | I26: 0 | J26: 0 | K26: 0 | L26: 0 | M26: 300 | N26: 300 | O26: 300 | P26: =SUM(D26:O26) -> 900 | Q26: 300 | R26: 300 | S26: 300 | T26: 300 | U26: 300 | V26: 300 | W26: 300 | X26: 300 | Y26: 300 | Z26: 300 | AA26: 300 | AB26: 300 | AC26: =SUM(Q26:AB26) -> 3600 | AD26: 0 | AE26: 0 | AF26: 0 | AG26: 0 | AH26: 0 | AI26: 0 | AJ26: 0 | AK26: 0 | AL26: 0 | AM26: 0 | AN26: 0 | AO26: 0 | AP26: =SUM(AD26:AO26) -> 0 | BC26: =SUM(AQ26:BB26) -> 0
B27: Anzeigen- und sonst. Werbung | D27: 0 | E27: 0 | F27: 0 | G27: 0 | H27: 0 | I27: 0 | J27: 0 | K27: 0 | L27: 0 | M27: 100 | N27: 100 | O27: 100 | P27: =SUM(D27:O27) -> 300 | Q27: 100 | R27: 100 | S27: 100 | T27: 100 | U27: 100 | V27: 100 | W27: 100 | X27: 100 | Y27: 100 | Z27: 100 | AA27: 100 | AB27: 100 | AC27: =SUM(Q27:AB27) -> 1200 | AD27: 0 | AE27: 0 | AF27: 0 | AG27: 0 | AH27: 0 | AI27: 0 | AJ27: 0 | AK27: 0 | AL27: 0 | AM27: 0 | AN27: 0 | AO27: 0 | AP27: =SUM(AD27:AO27) -> 0 | BC27: =SUM(AQ27:BB27) -> 0
B28: Kosten der Warenabgabe
C29: Verpackung/Ausgangsfrachten | D29: 0 | E29: 0 | F29: 0 | G29: 0 | H29: 0 | I29: 0 | J29: 0 | K29: 0 | L29: 0 | M29: 0 | N29: 0 | O29: 0 | P29: =SUM(D29:O29) -> 0 | Q29: 0 | R29: 0 | S29: 0 | T29: 0 | U29: 0 | V29: 0 | W29: 0 | X29: 0 | Y29: 0 | Z29: 0 | AA29: 0 | AB29: 0 | AC29: =SUM(Q29:AB29) -> 0 | AD29: 0 | AE29: 0 | AF29: 0 | AG29: 0 | AH29: 0 | AI29: 0 | AJ29: 0 | AK29: 0 | AL29: 0 | AM29: 0 | AN29: 0 | AO29: 0 | AP29: =SUM(AD29:AO29) -> 0 | BC29: =SUM(AQ29:BB29) -> 0
C30: Provisionen | D30: 0 | E30: 0 | F30: 0 | G30: 0 | H30: 0 | I30: 0 | J30: 0 | K30: 0 | L30: 0 | M30: 0 | N30: 0 | O30: 0 | P30: =SUM(D30:O30) -> 0 | Q30: 0 | R30: 0 | S30: 0 | T30: 0 | U30: 0 | V30: 0 | W30: 0 | X30: 0 | Y30: 0 | Z30: 0 | AA30: 0 | AB30: 0 | AC30: =SUM(Q30:AB30) -> 0 | AD30: 0 | AE30: 0 | AF30: 0 | AG30: 0 | AH30: 0 | AI30: 0 | AJ30: 0 | AK30: 0 | AL30: 0 | AM30: 0 | AN30: 0 | AO30: 0 | AP30: =SUM(AD30:AO30) -> 0 | BC30: =SUM(AQ30:BB30) -> 0
B31: Instandhaltung Betriebs- und Geschäftsausstattung | D31: 0 | E31: 0 | F31: 0 | G31: 0 | H31: 0 | I31: 0 | J31: 0 | K31: 0 | L31: 0 | M31: 0 | N31: 0 | O31: 0 | P31: =SUM(D31:O31) -> 0 | Q31: 0 | R31: 0 | S31: 0 | T31: 0 | U31: 0 | V31: 0 | W31: 0 | X31: 0 | Y31: 0 | Z31: 0 | AA31: 0 | AB31: 0 | AC31: =SUM(Q31:AB31) -> 0 | AD31: 0 | AE31: 0 | AF31: 0 | AG31: 0 | AH31: 0 | AI31: 0 | AJ31: 0 | AK31: 0 | AL31: 0 | AM31: 0 | AN31: 0 | AO31: 0 | AP31: =SUM(AD31:AO31) -> 0 | BC31: =SUM(AQ31:BB31) -> 0
B32: Leasing (außer Kfz) | D32: 0 | E32: 0 | F32: 0 | G32: 0 | H32: 0 | I32: 0 | J32: 0 | K32: 0 | L32: 0 | M32: 0 | N32: 0 | O32: 0 | P32: =SUM(D32:O32) -> 0 | Q32: 0 | R32: 0 | S32: 0 | T32: 0 | U32: 0 | V32: 0 | W32: 0 | X32: 0 | Y32: 0 | Z32: 0 | AA32: 0 | AB32: 0 | AC32: =SUM(Q32:AB32) -> 0 | AD32: 0 | AE32: 0 | AF32: 0 | AG32: 0 | AH32: 0 | AI32: 0 | AJ32: 0 | AK32: 0 | AL32: 0 | AM32: 0 | AN32: 0 | AO32: 0 | AP32: =SUM(AD32:AO32) -> 0 | BC32: =SUM(AQ32:BB32) -> 0
B33: Software-Updates | D33: 0 | E33: 0 | F33: 0 | G33: 0 | H33: 0 | I33: 0 | J33: 0 | K33: 0 | L33: 0 | M33: 40 | N33: 40 | O33: 40 | P33: =SUM(D33:O33) -> 120 | Q33: 40 | R33: 40 | S33: 40 | T33: 40 | U33: 40 | V33: 40 | W33: 40 | X33: 40 | Y33: 40 | Z33: 40 | AA33: 40 | AB33: 40 | AC33: =SUM(Q33:AB33) -> 480 | AD33: 0 | AE33: 0 | AF33: 0 | AG33: 0 | AH33: 0 | AI33: 0 | AJ33: 0 | AK33: 0 | AL33: 0 | AM33: 0 | AN33: 0 | AO33: 0 | AP33: =SUM(AD33:AO33) -> 0 | BC33: =SUM(AQ33:BB33) -> 0
B34: Versicherungen (ohne Kfz) | D34: 0 | E34: 0 | F34: 0 | G34: 0 | H34: 0 | I34: 0 | J34: 0 | K34: 0 | L34: 0 | M34: 40 | N34: 40 | O34: 40 | P34: =SUM(D34:O34) -> 120 | Q34: 40 | R34: 40 | S34: 40 | T34: 40 | U34: 40 | V34: 40 | W34: 40 | X34: 40 | Y34: 40 | Z34: 40 | AA34: 40 | AB34: 40 | AC34: =SUM(Q34:AB34) -> 480 | AD34: 0 | AE34: 0 | AF34: 0 | AG34: 0 | AH34: 0 | AI34: 0 | AJ34: 0 | AK34: 0 | AL34: 0 | AM34: 0 | AN34: 0 | AO34: 0 | AP34: =SUM(AD34:AO34) -> 0 | BC34: =SUM(AQ34:BB34) -> 0
B35: Beiträge, Gebühren | D35: 0 | E35: 0 | F35: 0 | G35: 0 | H35: 0 | I35: 0 | J35: 0 | K35: 0 | L35: 0 | M35: 15 | N35: 15 | O35: 15 | P35: =SUM(D35:O35) -> 45 | Q35: 15 | R35: 15 | S35: 15 | T35: 15 | U35: 15 | V35: 15 | W35: 15 | X35: 15 | Y35: 15 | Z35: 15 | AA35: 15 | AB35: 15 | AC35: =SUM(Q35:AB35) -> 180 | AD35: 0 | AE35: 0 | AF35: 0 | AG35: 0 | AH35: 0 | AI35: 0 | AJ35: 0 | AK35: 0 | AL35: 0 | AM35: 0 | AN35: 0 | AO35: 0 | AP35: =SUM(AD35:AO35) -> 0 | BC35: =SUM(AQ35:BB35) -> 0
B36: Bürobedarf | D36: 0 | E36: 0 | F36: 0 | G36: 0 | H36: 0 | I36: 0 | J36: 0 | K36: 0 | L36: 0 | M36: 30 | N36: 30 | O36: 30 | P36: =SUM(D36:O36) -> 90 | Q36: 30 | R36: 30 | S36: 30 | T36: 30 | U36: 30 | V36: 30 | W36: 30 | X36: 30 | Y36: 30 | Z36: 30 | AA36: 30 | AB36: 30 | AC36: =SUM(Q36:AB36) -> 360 | AD36: 0 | AE36: 0 | AF36: 0 | AG36: 0 | AH36: 0 | AI36: 0 | AJ36: 0 | AK36: 0 | AL36: 0 | AM36: 0 | AN36: 0 | AO36: 0 | AP36: =SUM(AD36:AO36) -> 0 | BC36: =SUM(AQ36:BB36) -> 0
B37: Postwertzeichen | D37: 0 | E37: 0 | F37: 0 | G37: 0 | H37: 0 | I37: 0 | J37: 0 | K37: 0 | L37: 0 | M37: 10 | N37: 10 | O37: 10 | P37: =SUM(D37:O37) -> 30 | Q37: 10 | R37: 10 | S37: 10 | T37: 10 | U37: 10 | V37: 10 | W37: 10 | X37: 10 | Y37: 10 | Z37: 10 | AA37: 10 | AB37: 10 | AC37: =SUM(Q37:AB37) -> 120 | AD37: 0 | AE37: 0 | AF37: 0 | AG37: 0 | AH37: 0 | AI37: 0 | AJ37: 0 | AK37: 0 | AL37: 0 | AM37: 0 | AN37: 0 | AO37: 0 | AP37: =SUM(AD37:AO37) -> 0 | BC37: =SUM(AQ37:BB37) -> 0
B38: Fachliteratur | D38: 0 | E38: 0 | F38: 0 | G38: 0 | H38: 0 | I38: 0 | J38: 0 | K38: 0 | L38: 0 | M38: 20 | N38: 20 | O38: 20 | P38: =SUM(D38:O38) -> 60 | Q38: 20 | R38: 20 | S38: 20 | T38: 20 | U38: 20 | V38: 20 | W38: 20 | X38: 20 | Y38: 20 | Z38: 20 | AA38: 20 | AB38: 20 | AC38: =SUM(Q38:AB38) -> 240 | AD38: 0 | AE38: 0 | AF38: 0 | AG38: 0 | AH38: 0 | AI38: 0 | AJ38: 0 | AK38: 0 | AL38: 0 | AM38: 0 | AN38: 0 | AO38: 0 | AP38: =SUM(AD38:AO38) -> 0 | BC38: =SUM(AQ38:BB38) -> 0
B39: Fortbildung | D39: 0 | E39: 0 | F39: 0 | G39: 0 | H39: 0 | I39: 0 | J39: 0 | K39: 0 | L39: 0 | M39: 0 | N39: 0 | O39: 0 | P39: =SUM(D39:O39) -> 0 | Q39: 0 | R39: 0 | S39: 0 | T39: 0 | U39: 0 | V39: 0 | W39: 0 | X39: 0 | Y39: 0 | Z39: 0 | AA39: 0 | AB39: 0 | AC39: =SUM(Q39:AB39) -> 0 | AD39: 0 | AE39: 0 | AF39: 0 | AG39: 0 | AH39: 0 | AI39: 0 | AJ39: 0 | AK39: 0 | AL39: 0 | AM39: 0 | AN39: 0 | AO39: 0 | AP39: =SUM(AD39:AO39) -> 0 | BC39: =SUM(AQ39:BB39) -> 0
B40: Messen und Ausstellungen | D40: 0 | E40: 0 | F40: 0 | G40: 0 | H40: 0 | I40: 0 | J40: 0 | K40: 0 | L40: 0 | M40: 0 | N40: 0 | O40: 0 | P40: =SUM(D40:O40) -> 0 | Q40: 0 | R40: 0 | S40: 0 | T40: 0 | U40: 0 | V40: 0 | W40: 0 | X40: 0 | Y40: 0 | Z40: 0 | AA40: 0 | AB40: 0 | AC40: =SUM(Q40:AB40) -> 0 | AD40: 0 | AE40: 0 | AF40: 0 | AG40: 0 | AH40: 0 | AI40: 0 | AJ40: 0 | AK40: 0 | AL40: 0 | AM40: 0 | AN40: 0 | AO40: 0 | AP40: =SUM(AD40:AO40) -> 0 | BC40: =SUM(AQ40:BB40) -> 0
...

Sheet Liquiditätsplan
D1: =+'Umsatzplan Dienstleistungen'!G1 -> Januar | E1: =+'Umsatzplan Dienstleistungen'!H1 -> Februar | F1: =+'Umsatzplan Dienstleistungen'!I1 -> März | G1: =+'Umsatzplan Dienstleistungen'!J1 -> April | H1: =+'Umsatzplan Dienstleistungen'!K1 -> Mai | I1: =+'Umsatzplan Dienstleistungen'!L1 -> Juni | J1: =+'Umsatzplan Dienstleistungen'!M1 -> Juli | K1: =+'Umsatzplan Dienstleistungen'!N1 -> August | ... O1: =+'Umsatzplan Dienstleistungen'!R1 -> Dezember | P1: =+gj -> 2026 | Q1: =+'Umsatzplan Dienstleistungen'!T1 -> Januar | R1: =+'Umsatzplan Dienstleistungen'!U1 -> Februar | S1: =+'Umsatzplan Dienstleistungen'!V1 -> März | T1: =+'Umsatzplan Dienstleistungen'!W1 -> April | U1: =+'Umsatzplan Dienstleistungen'!X1 -> Mai | V1: =+'Umsatzplan Dienstleistungen'!Y1 -> Juni | W1: =+'Umsatzplan Dienstleistungen'!Z1 -> Juli | X1: =+'Umsatzplan Dienstleistungen'!AA1 -> August | ... AB1: =+'Umsatzplan Dienstleistungen'!AE1 -> Dezember | AC1: =+gj+1 -> 2027 | AD1: =+'Umsatzplan Dienstleistungen'!AG1 -> Januar | AE1: =+'Umsatzplan Dienstleistungen'!AH1 -> Februar | AF1: =+'Umsatzplan Dienstleistungen'!AI1 -> März | AG1: =+'Umsatzplan Dienstleistungen'!AJ1 -> April | AH1: =+'Umsatzplan Dienstleistungen'!AK1 -> Mai | AI1: =+'Umsatzplan Dienstleistungen'!AL1 -> Juni | AJ1: =+'Umsatzplan Dienstleistungen'!AM1 -> Juli | AK1: =+'Umsatzplan Dienstleistungen'!AN1 -> August | ... AO1: =+'Umsatzplan Dienstleistungen'!AR1 -> Dezember | AP1: =+gj+2 -> 2028 | AQ1: =+'Umsatzplan Dienstleistungen'!AT1 -> Januar | AR1: =+'Umsatzplan Dienstleistungen'!AU1 -> Februar | AS1: =+'Umsatzplan Dienstleistungen'!AV1 -> März | AT1: =+'Umsatzplan Dienstleistungen'!AW1 -> April | AU1: =+'Umsatzplan Dienstleistungen'!AX1 -> Mai | AV1: =+'Umsatzplan Dienstleistungen'!AY1 -> Juni | AW1: =+'Umsatzplan Dienstleistungen'!AZ1 -> Juli | AX1: =+'Umsatzplan Dienstleistungen'!BA1 -> August | ... BB1: =+'Umsatzplan Dienstleistungen'!BE1 -> Dezember | BC1: =+gj+3 -> 2029
A2: Zahlungseingänge auf gebuchten Umsatz
B3: =IF('Infos vor dem Start'!$A$17="x","Bruttoumsatz Handel/Dienstleistungen","Umsatz Handel/Dienstleistungen") -> Bruttoumsatz Handel/Dienstleistungen
C4: =IF('Infos vor dem Start'!$A$17="x","Bruttoumsatz 19%","Umsatz") -> Bruttoumsatz 19% | D4: =IF(rechnung="x",0,+Rentabilitätsvorschau!D3*(1+USteins)) -> 0 | E4: =IF(rechnung="x",+Rentabilitätsvorschau!D3*(1+USteins),+Rentabilitätsvorschau!E3*(1+USteins)) -> 0 | F4: =IF(rechnung="x",+Rentabilitätsvorschau!E3*(1+USteins),+Rentabilitätsvorschau!F3*(1+USteins)) -> 0 | G4: =IF(rechnung="x",+Rentabilitätsvorschau!F3*(1+USteins),+Rentabilitätsvorschau!G3*(1+USteins)) -> 0 | H4: =IF(rechnung="x",+Rentabilitätsvorschau!G3*(1+USteins),+Rentabilitätsvorschau!H3*(1+USteins)) -> 0 | I4: =IF(rechnung="x",+Rentabilitätsvorschau!H3*(1+USteins),+Rentabilitätsvorschau!I3*(1+USteins)) -> 0 | J4: =IF(rechnung="x",+Rentabilitätsvorschau!I3*(1+USteins),+Rentabilitätsvorschau!J3*(1+USteins)) -> 0 | K4: =IF(rechnung="x",+Rentabilitätsvorschau!J3*(1+USteins),+Rentabilitätsvorschau!K3*(1+USteins)) -> 0 | L4: =IF(rechnung="x",+Rentabilitätsvorschau!K3*(1+USteins),+Rentabilitätsvorschau!L3*(1+USteins)) -> 0 | ... O4: =IF(rechnung="x",+Rentabilitätsvorschau!N3*(1+USteins),+Rentabilitätsvorschau!O3*(1+USteins)) -> 0 | P4: =SUM(D4:O4) -> 0 | Q4: =IF(rechnung="x",+Rentabilitätsvorschau!O3*(1+USteins),+Rentabilitätsvorschau!Q3*(1+USt)) -> 0 | R4: =IF(rechnung="x",+Rentabilitätsvorschau!Q3*(1+USt),+Rentabilitätsvorschau!R3*(1+USt)) -> 0 | S4: =IF(rechnung="x",+Rentabilitätsvorschau!R3*(1+USt),+Rentabilitätsvorschau!S3*(1+USt)) -> 0 | T4: =IF(rechnung="x",+Rentabilitätsvorschau!S3*(1+USt),+Rentabilitätsvorschau!T3*(1+USt)) -> 0 | U4: =IF(rechnung="x",+Rentabilitätsvorschau!T3*(1+USt),+Rentabilitätsvorschau!U3*(1+USt)) -> 0 | V4: =IF(rechnung="x",+Rentabilitätsvorschau!U3*(1+USt),+Rentabilitätsvorschau!V3*(1+USt)) -> 0 | W4: =IF(rechnung="x",+Rentabilitätsvorschau!V3*(1+USt),+Rentabilitätsvorschau!W3*(1+USt)) -> 0 | X4: =IF(rechnung="x",+Rentabilitätsvorschau!W3*(1+USt),+Rentabilitätsvorschau!X3*(1+USt)) -> 0 | Y4: =IF(rechnung="x",+Rentabilitätsvorschau!X3*(1+USt),+Rentabilitätsvorschau!Y3*(1+USt)) -> 0 | ... AB4: =IF(rechnung="x",+Rentabilitätsvorschau!AA3*(1+USt),+Rentabilitätsvorschau!AB3*(1+USt)) -> 0 | AC4: =SUM(Q4:AB4) -> 0 | AD4: =IF(rechnung="x",+Rentabilitätsvorschau!AB3*(1+USt),+Rentabilitätsvorschau!AD3*(1+USt)) -> 0 | AE4: =IF(rechnung="x",+Rentabilitätsvorschau!AD3*(1+USt),+Rentabilitätsvorschau!AE3*(1+USt)) -> 0 | AF4: =IF(rechnung="x",+Rentabilitätsvorschau!AE3*(1+USt),+Rentabilitätsvorschau!AF3*(1+USt)) -> 0 | AG4: =IF(rechnung="x",+Rentabilitätsvorschau!AF3*(1+USt),+Rentabilitätsvorschau!AG3*(1+USt)) -> 0 | AH4: =IF(rechnung="x",+Rentabilitätsvorschau!AG3*(1+USt),+Rentabilitätsvorschau!AH3*(1+USt)) -> 0 | AI4: =IF(rechnung="x",+Rentabilitätsvorschau!AH3*(1+USt),+Rentabilitätsvorschau!AI3*(1+USt)) -> 0 | AJ4: =IF(rechnung="x",+Rentabilitätsvorschau!AI3*(1+USt),+Rentabilitätsvorschau!AJ3*(1+USt)) -> 0 | AK4: =IF(rechnung="x",+Rentabilitätsvorschau!AJ3*(1+USt),+Rentabilitätsvorschau!AK3*(1+USt)) -> 0 | AL4: =IF(rechnung="x",+Rentabilitätsvorschau!AK3*(1+USt),+Rentabilitätsvorschau!AL3*(1+USt)) -> 0 | ... AO4: =IF(rechnung="x",+Rentabilitätsvorschau!AN3*(1+USt),+Rentabilitätsvorschau!AO3*(1+USt)) -> 0 | AP4: =SUM(AD4:AO4) -> 0 | AQ4: =IF(rechnung="x",+Rentabilitätsvorschau!AO3*(1+USt),+Rentabilitätsvorschau!AQ3*(1+USt)) -> 0 | AR4: =IF(rechnung="x",+Rentabilitätsvorschau!AQ3*(1+USt),+Rentabilitätsvorschau!AR3*(1+USt)) -> 0 | AS4: =IF(rechnung="x",+Rentabilitätsvorschau!AR3*(1+USt),+Rentabilitätsvorschau!AS3*(1+USt)) -> 0 | AT4: =IF(rechnung="x",+Rentabilitätsvorschau!AS3*(1+USt),+Rentabilitätsvorschau!AT3*(1+USt)) -> 0 | AU4: =IF(rechnung="x",+Rentabilitätsvorschau!AT3*(1+USt),+Rentabilitätsvorschau!AU3*(1+USt)) -> 0 | AV4: =IF(rechnung="x",+Rentabilitätsvorschau!AU3*(1+USt),+Rentabilitätsvorschau!AV3*(1+USt)) -> 0 | AW4: =IF(rechnung="x",+Rentabilitätsvorschau!AV3*(1+USt),+Rentabilitätsvorschau!AW3*(1+USt)) -> 0 | AX4: =IF(rechnung="x",+Rentabilitätsvorschau!AW3*(1+USt),+Rentabilitätsvorschau!AX3*(1+USt)) -> 0 | AY4: =IF(rechnung="x",+Rentabilitätsvorschau!AX3*(1+USt),+Rentabilitätsvorschau!AY3*(1+USt)) -> 0 | ... BB4: =IF(rechnung="x",+Rentabilitätsvorschau!BA3*(1+USt),+Rentabilitätsvorschau!BB3*(1+USt)) -> 0 | BC4: =SUM(AQ4:BB4) -> 0
C5: =IF('Infos vor dem Start'!$A$17="x","Bruttoumsatz 7%","Umsatz") -> Bruttoumsatz 7% | D5: =IF(rechnung="x",0,+Rentabilitätsvorschau!D4*(1+UStermeins)) -> 0 | E5: =IF(rechnung="x",+Rentabilitätsvorschau!D4*(1+UStermeins),+Rentabilitätsvorschau!E4*(1+UStermeins)) -> 0 | F5: =IF(rechnung="x",+Rentabilitätsvorschau!E4*(1+UStermeins),+Rentabilitätsvorschau!F4*(1+UStermeins)) -> 0 | G5: =IF(rechnung="x",+Rentabilitätsvorschau!F4*(1+UStermeins),+Rentabilitätsvorschau!G4*(1+UStermeins)) -> 0 | H5: =IF(rechnung="x",+Rentabilitätsvorschau!G4*(1+UStermeins),+Rentabilitätsvorschau!H4*(1+UStermeins)) -> 0 | I5: =IF(rechnung="x",+Rentabilitätsvorschau!H4*(1+UStermeins),+Rentabilitätsvorschau!I4*(1+UStermeins)) -> 0 | J5: =IF(rechnung="x",+Rentabilitätsvorschau!I4*(1+UStermeins),+Rentabilitätsvorschau!J4*(1+UStermeins)) -> 0 | K5: =IF(rechnung="x",+Rentabilitätsvorschau!J4*(1+UStermeins),+Rentabilitätsvorschau!K4*(1+UStermeins)) -> 0 | L5: =IF(rechnung="x",+Rentabilitätsvorschau!K4*(1+UStermeins),+Rentabilitätsvorschau!L4*(1+UStermeins)) -> 0 | ... O5: =IF(rechnung="x",+Rentabilitätsvorschau!N4*(1+UStermeins),+Rentabilitätsvorschau!O4*(1+UStermeins)) -> 0 | P5: =SUM(D5:O5) -> 0 | Q5: =IF(rechnung="x",+Rentabilitätsvorschau!O4*(1+UStermeins),+Rentabilitätsvorschau!Q4*(1+USterm)) -> 0 | R5: =IF(rechnung="x",+Rentabilitätsvorschau!Q4*(1+USterm),+Rentabilitätsvorschau!R4*(1+USterm)) -> 0 | S5: =IF(rechnung="x",+Rentabilitätsvorschau!R4*(1+USterm),+Rentabilitätsvorschau!S4*(1+USterm)) -> 0 | T5: =IF(rechnung="x",+Rentabilitätsvorschau!S4*(1+USterm),+Rentabilitätsvorschau!T4*(1+USterm)) -> 0 | U5: =IF(rechnung="x",+Rentabilitätsvorschau!T4*(1+USterm),+Rentabilitätsvorschau!U4*(1+USterm)) -> 0 | V5: =IF(rechnung="x",+Rentabilitätsvorschau!U4*(1+USterm),+Rentabilitätsvorschau!V4*(1+USterm)) -> 0 | W5: =IF(rechnung="x",+Rentabilitätsvorschau!V4*(1+USterm),+Rentabilitätsvorschau!W4*(1+USterm)) -> 0 | X5: =IF(rechnung="x",+Rentabilitätsvorschau!W4*(1+USterm),+Rentabilitätsvorschau!X4*(1+USterm)) -> 0 | Y5: =IF(rechnung="x",+Rentabilitätsvorschau!X4*(1+USterm),+Rentabilitätsvorschau!Y4*(1+USterm)) -> 0 | ... AB5: =IF(rechnung="x",+Rentabilitätsvorschau!AA4*(1+USterm),+Rentabilitätsvorschau!AB4*(1+USterm)) -> 0 | AC5: =SUM(Q5:AB5) -> 0 | AD5: =IF(rechnung="x",+Rentabilitätsvorschau!AB4*(1+USterm),+Rentabilitätsvorschau!AD4*(1+USterm)) -> 0 | AE5: =IF(rechnung="x",+Rentabilitätsvorschau!AD4*(1+USterm),+Rentabilitätsvorschau!AE4*(1+USterm)) -> 0 | AF5: =IF(rechnung="x",+Rentabilitätsvorschau!AE4*(1+USterm),+Rentabilitätsvorschau!AF4*(1+USterm)) -> 0 | AG5: =IF(rechnung="x",+Rentabilitätsvorschau!AF4*(1+USterm),+Rentabilitätsvorschau!AG4*(1+USterm)) -> 0 | AH5: =IF(rechnung="x",+Rentabilitätsvorschau!AG4*(1+USterm),+Rentabilitätsvorschau!AH4*(1+USterm)) -> 0 | AI5: =IF(rechnung="x",+Rentabilitätsvorschau!AH4*(1+USterm),+Rentabilitätsvorschau!AI4*(1+USterm)) -> 0 | AJ5: =IF(rechnung="x",+Rentabilitätsvorschau!AI4*(1+USterm),+Rentabilitätsvorschau!AJ4*(1+USterm)) -> 0 | AK5: =IF(rechnung="x",+Rentabilitätsvorschau!AJ4*(1+USterm),+Rentabilitätsvorschau!AK4*(1+USterm)) -> 0 | AL5: =IF(rechnung="x",+Rentabilitätsvorschau!AK4*(1+USterm),+Rentabilitätsvorschau!AL4*(1+USterm)) -> 0 | ... AO5: =IF(rechnung="x",+Rentabilitätsvorschau!AN4*(1+USterm),+Rentabilitätsvorschau!AO4*(1+USterm)) -> 0 | AP5: =SUM(AD5:AO5) -> 0 | AQ5: =IF(rechnung="x",+Rentabilitätsvorschau!AO4*(1+USterm),+Rentabilitätsvorschau!AQ4*(1+USterm)) -> 0 | AR5: =IF(rechnung="x",+Rentabilitätsvorschau!AQ4*(1+USterm),+Rentabilitätsvorschau!AR4*(1+USterm)) -> 0 | AS5: =IF(rechnung="x",+Rentabilitätsvorschau!AR4*(1+USterm),+Rentabilitätsvorschau!AS4*(1+USterm)) -> 0 | AT5: =IF(rechnung="x",+Rentabilitätsvorschau!AS4*(1+USterm),+Rentabilitätsvorschau!AT4*(1+USterm)) -> 0 | AU5: =IF(rechnung="x",+Rentabilitätsvorschau!AT4*(1+USterm),+Rentabilitätsvorschau!AU4*(1+USterm)) -> 0 | AV5: =IF(rechnung="x",+Rentabilitätsvorschau!AU4*(1+USterm),+Rentabilitätsvorschau!AV4*(1+USterm)) -> 0 | AW5: =IF(rechnung="x",+Rentabilitätsvorschau!AV4*(1+USterm),+Rentabilitätsvorschau!AW4*(1+USterm)) -> 0 | AX5: =IF(rechnung="x",+Rentabilitätsvorschau!AW4*(1+USterm),+Rentabilitätsvorschau!AX4*(1+USterm)) -> 0 | AY5: =IF(rechnung="x",+Rentabilitätsvorschau!AX4*(1+USterm),+Rentabilitätsvorschau!AY4*(1+USterm)) -> 0 | ... BB5: =IF(rechnung="x",+Rentabilitätsvorschau!BA4*(1+USterm),+Rentabilitätsvorschau!BB4*(1+USterm)) -> 0 | BC5: =SUM(AQ5:BB5) -> 0
B6: =IF('Infos vor dem Start'!$A$17="x","Bruttoumsatz Dienstleistungen 19%","Umsatz Dienstleistungen") -> Bruttoumsatz Dienstleistungen 19% | D6: =IF(rechnung="x",0,+Rentabilitätsvorschau!D5*(1+USteins)) -> 0 | E6: =IF(rechnung="x",+Rentabilitätsvorschau!D5*(1+USteins),+Rentabilitätsvorschau!E5*(1+USteins)) -> 0 | F6: =IF(rechnung="x",+Rentabilitätsvorschau!E5*(1+USteins),+Rentabilitätsvorschau!F5*(1+USteins)) -> 0 | G6: =IF(rechnung="x",+Rentabilitätsvorschau!F5*(1+USteins),+Rentabilitätsvorschau!G5*(1+USteins)) -> 0 | H6: =IF(rechnung="x",+Rentabilitätsvorschau!G5*(1+USteins),+Rentabilitätsvorschau!H5*(1+USteins)) -> 0 | I6: =IF(rechnung="x",+Rentabilitätsvorschau!H5*(1+USteins),+Rentabilitätsvorschau!I5*(1+USteins)) -> 0 | J6: =IF(rechnung="x",+Rentabilitätsvorschau!I5*(1+USteins),+Rentabilitätsvorschau!J5*(1+USteins)) -> 0 | K6: =IF(rechnung="x",+Rentabilitätsvorschau!J5*(1+USteins),+Rentabilitätsvorschau!K5*(1+USteins)) -> 0 | L6: =IF(rechnung="x",+Rentabilitätsvorschau!K5*(1+USteins),+Rentabilitätsvorschau!L5*(1+USteins)) -> 0 | ... O6: =IF(rechnung="x",+Rentabilitätsvorschau!N5*(1+USteins),+Rentabilitätsvorschau!O5*(1+USteins)) -> 0 | P6: =SUM(D6:O6) -> 16660 | Q6: =IF(rechnung="x",+Rentabilitätsvorschau!O5*(1+USteins),+Rentabilitätsvorschau!Q5*(1+USt)) -> 21420 | R6: =IF(rechnung="x",+Rentabilitätsvorschau!Q5*(1+USt),+Rentabilitätsvorschau!R5*(1+USt)) -> 0 | S6: =IF(rechnung="x",+Rentabilitätsvorschau!R5*(1+USt),+Rentabilitätsvorschau!S5*(1+USt)) -> 0 | T6: =IF(rechnung="x",+Rentabilitätsvorschau!S5*(1+USt),+Rentabilitätsvorschau!T5*(1+USt)) -> 0 | U6: =IF(rechnung="x",+Rentabilitätsvorschau!T5*(1+USt),+Rentabilitätsvorschau!U5*(1+USt)) -> 0 | V6: =IF(rechnung="x",+Rentabilitätsvorschau!U5*(1+USt),+Rentabilitätsvorschau!V5*(1+USt)) -> 0 | W6: =IF(rechnung="x",+Rentabilitätsvorschau!V5*(1+USt),+Rentabilitätsvorschau!W5*(1+USt)) -> 0 | X6: =IF(rechnung="x",+Rentabilitätsvorschau!W5*(1+USt),+Rentabilitätsvorschau!X5*(1+USt)) -> 0 | Y6: =IF(rechnung="x",+Rentabilitätsvorschau!X5*(1+USt),+Rentabilitätsvorschau!Y5*(1+USt)) -> 0 | ... AB6: =IF(rechnung="x",+Rentabilitätsvorschau!AA5*(1+USt),+Rentabilitätsvorschau!AB5*(1+USt)) -> 0 | AC6: =SUM(Q6:AB6) -> 21420 | AD6: =IF(rechnung="x",+Rentabilitätsvorschau!AB5*(1+USt),+Rentabilitätsvorschau!AD5*(1+USt)) -> 0 | AE6: =IF(rechnung="x",+Rentabilitätsvorschau!AD5*(1+USt),+Rentabilitätsvorschau!AE5*(1+USt)) -> 0 | AF6: =IF(rechnung="x",+Rentabilitätsvorschau!AE5*(1+USt),+Rentabilitätsvorschau!AF5*(1+USt)) -> 0 | AG6: =IF(rechnung="x",+Rentabilitätsvorschau!AF5*(1+USt),+Rentabilitätsvorschau!AG5*(1+USt)) -> 0 | AH6: =IF(rechnung="x",+Rentabilitätsvorschau!AG5*(1+USt),+Rentabilitätsvorschau!AH5*(1+USt)) -> 0 | AI6: =IF(rechnung="x",+Rentabilitätsvorschau!AH5*(1+USt),+Rentabilitätsvorschau!AI5*(1+USt)) -> 0 | AJ6: =IF(rechnung="x",+Rentabilitätsvorschau!AI5*(1+USt),+Rentabilitätsvorschau!AJ5*(1+USt)) -> 0 | AK6: =IF(rechnung="x",+Rentabilitätsvorschau!AJ5*(1+USt),+Rentabilitätsvorschau!AK5*(1+USt)) -> 0 | AL6: =IF(rechnung="x",+Rentabilitätsvorschau!AK5*(1+USt),+Rentabilitätsvorschau!AL5*(1+USt)) -> 0 | ... AO6: =IF(rechnung="x",+Rentabilitätsvorschau!AN5*(1+USt),+Rentabilitätsvorschau!AO5*(1+USt)) -> 0 | AP6: =SUM(AD6:AO6) -> 0 | AQ6: =IF(rechnung="x",+Rentabilitätsvorschau!AO5*(1+USt),+Rentabilitätsvorschau!AQ5*(1+USt)) -> 0 | AR6: =IF(rechnung="x",+Rentabilitätsvorschau!AQ5*(1+USt),+Rentabilitätsvorschau!AR5*(1+USt)) -> 0 | AS6: =IF(rechnung="x",+Rentabilitätsvorschau!AR5*(1+USt),+Rentabilitätsvorschau!AS5*(1+USt)) -> 0 | AT6: =IF(rechnung="x",+Rentabilitätsvorschau!AS5*(1+USt),+Rentabilitätsvorschau!AT5*(1+USt)) -> 0 | AU6: =IF(rechnung="x",+Rentabilitätsvorschau!AT5*(1+USt),+Rentabilitätsvorschau!AU5*(1+USt)) -> 0 | AV6: =IF(rechnung="x",+Rentabilitätsvorschau!AU5*(1+USt),+Rentabilitätsvorschau!AV5*(1+USt)) -> 0 | AW6: =IF(rechnung="x",+Rentabilitätsvorschau!AV5*(1+USt),+Rentabilitätsvorschau!AW5*(1+USt)) -> 0 | AX6: =IF(rechnung="x",+Rentabilitätsvorschau!AW5*(1+USt),+Rentabilitätsvorschau!AX5*(1+USt)) -> 0 | AY6: =IF(rechnung="x",+Rentabilitätsvorschau!AX5*(1+USt),+Rentabilitätsvorschau!AY5*(1+USt)) -> 0 | ... BB6: =IF(rechnung="x",+Rentabilitätsvorschau!BA5*(1+USt),+Rentabilitätsvorschau!BB5*(1+USt)) -> 0 | BC6: =SUM(AQ6:BB6) -> 0
